Workbook

Sheet Jan
A1: PREASONT REPORT IN THE MONTH OF JAN 2015
A3: A - ABSENT | B3: L - LEAVE | F3: WO - WEEKLY OFF | K3: PH - PUBLIC HOLIDAY | P3: CO - COMP. OFF | U3: ML - MEDICAL. LEAVE | AA3: ODK - WORK AT KARAI
B4: CALENDER DATES
A5: NAME | B5: 1 | C5: 2 | D5: 3 | E5: 4 | F5: 5 | G5: 6 | H5: 7 | I5: 8 | J5: 9 | K5: 10 | L5: 11 | M5: 12 | N5: 13 | O5: 14 | P5: 15 | Q5: 16 | R5: 17 | S5: 18 | T5: 19 | U5: 20 | V5: 21 | W5: 22 | X5: 23 | Y5: 24 | Z5: 25 | AA5: 26 | AB5: 27 | AC5: 28 | AD5: 29 | AE5: 30 | AF5: 31 | AG5: P | AH5: ODK | AI5: A | AJ5: L | AK5: WO | AL5: PH | AM5: CO | AN5: ML | AO5: REMARKS
A6: PETER NORONHA | B6: P | C6: P | D6: l | AG6: =COUNTIF($B6:$AF6,$AG$5) | AH6: =COUNTIF($B6:$AF6,$AH$5) | AI6: =COUNTIF($B6:$AF6,$AI$5) | AJ6: =COUNTIF($B6:$AF6,$AJ$5) | AK6: =COUNTIF($B6:$AF6,$AK$5) | AL6: =COUNTIF($B6:$AF6,$AL$5) | AM6: =COUNTIF($B6:$AF6,$AM$5) | AN6: =COUNTIF($B6:$AF6,$AN$5) | AO6: 1 COM-OFF
A7: PETER NORONHA | B7: P | C7: P | D7: l | AG7: =COUNTIF($B7:$AF7,$AG$5) | AH7: =COUNTIF($B7:$AF7,$AH$5) | AI7: =COUNTIF($B7:$AF7,$AI$5) | AJ7: =COUNTIF($B7:$AF7,$AJ$5) | AK7: =COUNTIF($B7:$AF7,$AK$5) | AL7: =COUNTIF($B7:$AF7,$AL$5) | AM7: =COUNTIF($B7:$AF7,$AM$5) | AN7: =COUNTIF($B7:$AF7,$AN$5)
A8: SHYAMBALI PAL | B8: p | C8: a | D8: l | AG8: =COUNTIF($B8:$AF8,$AG$5) | AH8: =COUNTIF($B8:$AF8,$AH$5) | AI8: =COUNTIF($B8:$AF8,$AI$5) | AJ8: =COUNTIF($B8:$AF8,$AJ$5) | AK8: =COUNTIF($B8:$AF8,$AK$5) | AL8: =COUNTIF($B8:$AF8,$AL$5) | AM8: =COUNTIF($B8:$AF8,$AM$5) | AN8: =COUNTIF($B8:$AF8,$AN$5)
A9: SHYAMBALI PAL | B9: p | C9: a | D9: l | AG9: =COUNTIF($B9:$AF9,$AG$5) | AH9: =COUNTIF($B9:$AF9,$AH$5) | AI9: =COUNTIF($B9:$AF9,$AI$5) | AJ9: =COUNTIF($B9:$AF9,$AJ$5) | AK9: =COUNTIF($B9:$AF9,$AK$5) | AL9: =COUNTIF($B9:$AF9,$AL$5) | AM9: =COUNTIF($B9:$AF9,$AM$5) | AN9: =COUNTIF($B9:$AF9,$AN$5)
A10: SHATRUDHAN MAHATO | D10: l | AG10: =COUNTIF($B10:$AF10,$AG$5) | AH10: =COUNTIF($B10:$AF10,$AH$5) | AI10: =COUNTIF($B10:$AF10,$AI$5) | AJ10: =COUNTIF($B10:$AF10,$AJ$5) | AK10: =COUNTIF($B10:$AF10,$AK$5) | AL10: =COUNTIF($B10:$AF10,$AL$5) | AM10: =COUNTIF($B10:$AF10,$AM$5) | AN10: =COUNTIF($B10:$AF10,$AN$5)
A11: SHATRUDHAN MAHATO | D11: l | AG11: =COUNTIF($B11:$AF11,$AG$5) | AH11: =COUNTIF($B11:$AF11,$AH$5) | AI11: =COUNTIF($B11:$AF11,$AI$5) | AJ11: =COUNTIF($B11:$AF11,$AJ$5) | AK11: =COUNTIF($B11:$AF11,$AK$5) | AL11: =COUNTIF($B11:$AF11,$AL$5) | AM11: =COUNTIF($B11:$AF11,$AM$5) | AN11: =COUNTIF($B11:$AF11,$AN$5)
A12: RAVINDRA V. GOVEKAR | AG12: =COUNTIF($B12:$AF12,$AG$5) | AH12: =COUNTIF($B12:$AF12,$AH$5) | AI12: =COUNTIF($B12:$AF12,$AI$5) | AJ12: =COUNTIF($B12:$AF12,$AJ$5) | AK12: =COUNTIF($B12:$AF12,$AK$5) | AL12: =COUNTIF($B12:$AF12,$AL$5) | AM12: =COUNTIF($B12:$AF12,$AM$5) | AN12: =COUNTIF($B12:$AF12,$AN$5)
A13: RAVINDRA V. GOVEKAR | AG13: =COUNTIF($B13:$AF13,$AG$5) | AH13: =COUNTIF($B13:$AF13,$AH$5) | AI13: =COUNTIF($B13:$AF13,$AI$5) | AJ13: =COUNTIF($B13:$AF13,$AJ$5) | AK13: =COUNTIF($B13:$AF13,$AK$5) | AL13: =COUNTIF($B13:$AF13,$AL$5) | AM13: =COUNTIF($B13:$AF13,$AM$5) | AN13: =COUNTIF($B13:$AF13,$AN$5)
A14: DEEPAK WARPE | AG14: =COUNTIF($B14:$AF14,$AG$5) | AH14: =COUNTIF($B14:$AF14,$AH$5) | AI14: =COUNTIF($B14:$AF14,$AI$5) | AJ14: =COUNTIF($B14:$AF14,$AJ$5) | AK14: =COUNTIF($B14:$AF14,$AK$5) | AL14: =COUNTIF($B14:$AF14,$AL$5) | AM14: =COUNTIF($B14:$AF14,$AM$5) | AN14: =COUNTIF($B14:$AF14,$AN$5)
A15: DEEPAK WARPE | AG15: =COUNTIF($B15:$AF15,$AG$5) | AH15: =COUNTIF($B15:$AF15,$AH$5) | AI15: =COUNTIF($B15:$AF15,$AI$5) | AJ15: =COUNTIF($B15:$AF15,$AJ$5) | AK15: =COUNTIF($B15:$AF15,$AK$5) | AL15: =COUNTIF($B15:$AF15,$AL$5) | AM15: =COUNTIF($B15:$AF15,$AM$5) | AN15: =COUNTIF($B15:$AF15,$AN$5)
A16: RAVINDRA G. GOVEKAR | AG16: =COUNTIF($B16:$AF16,$AG$5) | AH16: =COUNTIF($B16:$AF16,$AH$5) | AI16: =COUNTIF($B16:$AF16,$AI$5) | AJ16: =COUNTIF($B16:$AF16,$AJ$5) | AK16: =COUNTIF($B16:$AF16,$AK$5) | AL16: =COUNTIF($B16:$AF16,$AL$5) | AM16: =COUNTIF($B16:$AF16,$AM$5) | AN16: =COUNTIF($B16:$AF16,$AN$5)
A17: RAVINDRA G. GOVEKAR | AG17: =COUNTIF($B17:$AF17,$AG$5) | AH17: =COUNTIF($B17:$AF17,$AH$5) | AI17: =COUNTIF($B17:$AF17,$AI$5) | AJ17: =COUNTIF($B17:$AF17,$AJ$5) | AK17: =COUNTIF($B17:$AF17,$AK$5) | AL17: =COUNTIF($B17:$AF17,$AL$5) | AM17: =COUNTIF($B17:$AF17,$AM$5) | AN17: =COUNTIF($B17:$AF17,$AN$5)
A18: JOEL FERNANDES | AG18: =COUNTIF($B18:$AF18,$AG$5) | AH18: =COUNTIF($B18:$AF18,$AH$5) | AI18: =COUNTIF($B18:$AF18,$AI$5) | AJ18: =COUNTIF($B18:$AF18,$AJ$5) | AK18: =COUNTIF($B18:$AF18,$AK$5) | AL18: =COUNTIF($B18:$AF18,$AL$5) | AM18: =COUNTIF($B18:$AF18,$AM$5) | AN18: =COUNTIF($B18:$AF18,$AN$5)
A19: JOEL FERNANDES | AG19: =COUNTIF($B19:$AF19,$AG$5) | AH19: =COUNTIF($B19:$AF19,$AH$5) | AI19: =COUNTIF($B19:$AF19,$AI$5) | AJ19: =COUNTIF($B19:$AF19,$AJ$5) | AK19: =COUNTIF($B19:$AF19,$AK$5) | AL19: =COUNTIF($B19:$AF19,$AL$5) | AM19: =COUNTIF($B19:$AF19,$AM$5) | AN19: =COUNTIF($B19:$AF19,$AN$5)
A20: RUZAR VAZ | AG20: =COUNTIF($B20:$AF20,$AG$5) | AH20: =COUNTIF($B20:$AF20,$AH$5) | AI20: =COUNTIF($B20:$AF20,$AI$5) | AJ20: =COUNTIF($B20:$AF20,$AJ$5) | AK20: =COUNTIF($B20:$AF20,$AK$5) | AL20: =COUNTIF($B20:$AF20,$AL$5) | AM20: =COUNTIF($B20:$AF20,$AM$5) | AN20: =COUNTIF($B20:$AF20,$AN$5)
A21: RUZAR VAZ | AG21: =COUNTIF($B21:$AF21,$AG$5) | AH21: =COUNTIF($B21:$AF21,$AH$5) | AI21: =COUNTIF($B21:$AF21,$AI$5) | AJ21: =COUNTIF($B21:$AF21,$AJ$5) | AK21: =COUNTIF($B21:$AF21,$AK$5) | AL21: =COUNTIF($B21:$AF21,$AL$5) | AM21: =COUNTIF($B21:$AF21,$AM$5) | AN21: =COUNTIF($B21:$AF21,$AN$5)
A22: DHARMENDRA KUMAR | AG22: =COUNTIF($B22:$AF22,$AG$5) | AH22: =COUNTIF($B22:$AF22,$AH$5) | AI22: =COUNTIF($B22:$AF22,$AI$5) | AJ22: =COUNTIF($B22:$AF22,$AJ$5) | AK22: =COUNTIF($B22:$AF22,$AK$5) | AL22: =COUNTIF($B22:$AF22,$AL$5) | AM22: =COUNTIF($B22:$AF22,$AM$5) | AN22: =COUNTIF($B22:$AF22,$AN$5)
A23: DHARMENDRA KUMAR | AG23: =COUNTIF($B23:$AF23,$AG$5) | AH23: =COUNTIF($B23:$AF23,$AH$5) | AI23: =COUNTIF($B23:$AF23,$AI$5) | AJ23: =COUNTIF($B23:$AF23,$AJ$5) | AK23: =COUNTIF($B23:$AF23,$AK$5) | AL23: =COUNTIF($B23:$AF23,$AL$5) | AM23: =COUNTIF($B23:$AF23,$AM$5) | AN23: =COUNTIF($B23:$AF23,$AN$5)
... A25: RESHMA KHOLKAR | AG25: =COUNTIF($B25:$AF25,$AG$5) | AH25: =COUNTIF($B25:$AF25,$AH$5) | AI25: =COUNTIF($B25:$AF25,$AI$5) | AJ25: =COUNTIF($B25:$AF25,$AJ$5) | AK25: =COUNTIF($B25:$AF25,$AK$5) | AL25: =COUNTIF($B25:$AF25,$AL$5) | AM25: =COUNTIF($B25:$AF25,$AM$5) | AN25: =COUNTIF($B25:$AF25,$AN$5)
AG26: =COUNTIF($B26:$AF26,$AG$5) | AH26: =COUNTIF($B26:$AF26,$AH$5) | AI26: =COUNTIF($B26:$AF26,$AI$5) | AJ26: =COUNTIF($B26:$AF26,$AJ$5) | AK26: =COUNTIF($B26:$AF26,$AK$5) | AL26: =COUNTIF($B26:$AF26,$AL$5) | AM26: =COUNTIF($B26:$AF26,$AM$5) | AN26: =COUNTIF($B26:$AF26,$AN$5)
AG27: =COUNTIF($B27:$AF27,$AG$5) | AH27: =COUNTIF($B27:$AF27,$AH$5) | AI27: =COUNTIF($B27:$AF27,$AI$5) | AJ27: =COUNTIF($B27:$AF27,$AJ$5) | AK27: =COUNTIF($B27:$AF27,$AK$5) | AL27: =COUNTIF($B27:$AF27,$AL$5) | AM27: =COUNTIF($B27:$AF27,$AM$5) | AN27: =COUNTIF($B27:$AF27,$AN$5)
AG28: =COUNTIF($B28:$AF28,$AG$5) | AH28: =COUNTIF($B28:$AF28,$AH$5) | AI28: =COUNTIF($B28:$AF28,$AI$5) | AJ28: =COUNTIF($B28:$AF28,$AJ$5) | AK28: =COUNTIF($B28:$AF28,$AK$5) | AL28: =COUNTIF($B28:$AF28,$AL$5) | AM28: =COUNTIF($B28:$AF28,$AM$5) | AN28: =COUNTIF($B28:$AF28,$AN$5)
AG29: =COUNTIF($B29:$AF29,$AG$5) | AH29: =COUNTIF($B29:$AF29,$AH$5) | AI29: =COUNTIF($B29:$AF29,$AI$5) | AJ29: =COUNTIF($B29:$AF29,$AJ$5) | AK29: =COUNTIF($B29:$AF29,$AK$5) | AL29: =COUNTIF($B29:$AF29,$AL$5) | AM29: =COUNTIF($B29:$AF29,$AM$5) | AN29: =COUNTIF($B29:$AF29,$AN$5)
AG30: =COUNTIF($B30:$AF30,$AG$5) | AH30: =COUNTIF($B30:$AF30,$AH$5) | AI30: =COUNTIF($B30:$AF30,$AI$5) | AJ30: =COUNTIF($B30:$AF30,$AJ$5) | AK30: =COUNTIF($B30:$AF30,$AK$5) | AL30: =COUNTIF($B30:$AF30,$AL$5) | AM30: =COUNTIF($B30:$AF30,$AM$5) | AN30: =COUNTIF($B30:$AF30,$AN$5)
AG31: =COUNTIF($B31:$AF31,$AG$5) | AH31: =COUNTIF($B31:$AF31,$AH$5) | AI31: =COUNTIF($B31:$AF31,$AI$5) | AJ31: =COUNTIF($B31:$AF31,$AJ$5) | AK31: =COUNTIF($B31:$AF31,$AK$5) | AL31: =COUNTIF($B31:$AF31,$AL$5) | AM31: =COUNTIF($B31:$AF31,$AM$5) | AN31: =COUNTIF($B31:$AF31,$AN$5)
AG32: =COUNTIF($B32:$AF32,$AG$5) | AH32: =COUNTIF($B32:$AF32,$AH$5) | AI32: =COUNTIF($B32:$AF32,$AI$5) | AJ32: =COUNTIF($B32:$AF32,$AJ$5) | AK32: =COUNTIF($B32:$AF32,$AK$5) | AL32: =COUNTIF($B32:$AF32,$AL$5) | AM32: =COUNTIF($B32:$AF32,$AM$5) | AN32: =COUNTIF($B32:$AF32,$AN$5)
AG33: =COUNTIF($B33:$AF33,$AG$5) | AH33: =COUNTIF($B33:$AF33,$AH$5) | AI33: =COUNTIF($B33:$AF33,$AI$5) | AJ33: =COUNTIF($B33:$AF33,$AJ$5) | AK33: =COUNTIF($B33:$AF33,$AK$5) | AL33: =COUNTIF($B33:$AF33,$AL$5) | AM33: =COUNTIF($B33:$AF33,$AM$5) | AN33: =COUNTIF($B33:$AF33,$AN$5)
AG34: =COUNTIF($B34:$AF34,$AG$5) | AH34: =COUNTIF($B34:$AF34,$AH$5) | AI34: =COUNTIF($B34:$AF34,$AI$5) | AJ34: =COUNTIF($B34:$AF34,$AJ$5) | AK34: =COUNTIF($B34:$AF34,$AK$5) | AL34: =COUNTIF($B34:$AF34,$AL$5) | AM34: =COUNTIF($B34:$AF34,$AM$5) | AN34: =COUNTIF($B34:$AF34,$AN$5)
AG35: =COUNTIF($B35:$AF35,$AG$5) | AH35: =COUNTIF($B35:$AF35,$AH$5) | AI35: =COUNTIF($B35:$AF35,$AI$5) | AJ35: =COUNTIF($B35:$AF35,$AJ$5) | AK35: =COUNTIF($B35:$AF35,$AK$5) | AL35: =COUNTIF($B35:$AF35,$AL$5) | AM35: =COUNTIF($B35:$AF35,$AM$5) | AN35: =COUNTIF($B35:$AF35,$AN$5)
AG36: =COUNTIF($B36:$AF36,$AG$5) | AH36: =COUNTIF($B36:$AF36,$AH$5) | AI36: =COUNTIF($B36:$AF36,$AI$5) | AJ36: =COUNTIF($B36:$AF36,$AJ$5) | AK36: =COUNTIF($B36:$AF36,$AK$5) | AL36: =COUNTIF($B36:$AF36,$AL$5) | AM36: =COUNTIF($B36:$AF36,$AM$5) | AN36: =COUNTIF($B36:$AF36,$AN$5)
AG37: =COUNTIF($B37:$AF37,$AG$5) | AH37: =COUNTIF($B37:$AF37,$AH$5) | AI37: =COUNTIF($B37:$AF37,$AI$5) | AJ37: =COUNTIF($B37:$AF37,$AJ$5) | AK37: =COUNTIF($B37:$AF37,$AK$5) | AL37: =COUNTIF($B37:$AF37,$AL$5) | AM37: =COUNTIF($B37:$AF37,$AM$5) | AN37: =COUNTIF($B37:$AF37,$AN$5)
... AG49: =COUNTIF($B49:$AF49,$AG$5) | AH49: =COUNTIF($B49:$AF49,$AH$5) | AI49: =COUNTIF($B49:$AF49,$AI$5) | AJ49: =COUNTIF($B49:$AF49,$AJ$5) | AK49: =COUNTIF($B49:$AF49,$AK$5) | AL49: =COUNTIF($B49:$AF49,$AL$5) | AM49: =COUNTIF($B49:$AF49,$AM$5) | AN49: =COUNTIF($B49:$AF49,$AN$5)

Sheet Feb
A1: PREASONT REPORT IN THE MONTH OF FEB 2015
A3: A - ABSENT | B3: L - LEAVE | F3: WO - WEEKLY OFF | K3: PH - PUBLIC HOLIDAY | P3: CO - COMP. OFF | U3: ML - MEDICAL. LEAVE | AA3: ODK - WORK AT KARAI
B4: CALENDER DATES
A5: NAME | B5: 1 | C5: 2 | D5: 3 | E5: 4 | F5: 5 | G5: 6 | H5: 7 | I5: 8 | J5: 9 | K5: 10 | L5: 11 | M5: 12 | N5: 13 | O5: 14 | P5: 15 | Q5: 16 | R5: 17 | S5: 18 | T5: 19 | U5: 20 | V5: 21 | W5: 22 | X5: 23 | Y5: 24 | Z5: 25 | AA5: 26 | AB5: 27 | AC5: 28 | AD5: 29 | AE5: 30 | AF5: 31 | AG5: P | AH5: ODK | AI5: A | AJ5: L | AK5: WO | AL5: PH | AM5: CO | AN5: ML | AO5: REMARKS
A6: =Jan!A6 | AG6: =COUNTIF($B6:$AF6,$AG$5) | AH6: =COUNTIF($B6:$AF6,$AH$5) | AI6: =COUNTIF($B6:$AF6,$AI$5) | AJ6: =COUNTIF($B6:$AF6,$AJ$5) | AK6: =COUNTIF($B6:$AF6,$AK$5) | AL6: =COUNTIF($B6:$AF6,$AL$5) | AM6: =COUNTIF($B6:$AF6,$AM$5) | AN6: =COUNTIF($B6:$AF6,$AN$5) | AO6: 1 COM-OFF
AG7: =COUNTIF($B7:$AF7,$AG$5) | AH7: =COUNTIF($B7:$AF7,$AH$5) | AI7: =COUNTIF($B7:$AF7,$AI$5) | AJ7: =COUNTIF($B7:$AF7,$AJ$5) | AK7: =COUNTIF($B7:$AF7,$AK$5) | AL7: =COUNTIF($B7:$AF7,$AL$5) | AM7: =COUNTIF($B7:$AF7,$AM$5) | AN7: =COUNTIF($B7:$AF7,$AN$5)
A8: =Jan!A8 | AG8: =COUNTIF($B8:$AF8,$AG$5) | AH8: =COUNTIF($B8:$AF8,$AH$5) | AI8: =COUNTIF($B8:$AF8,$AI$5) | AJ8: =COUNTIF($B8:$AF8,$AJ$5) | AK8: =COUNTIF($B8:$AF8,$AK$5) | AL8: =COUNTIF($B8:$AF8,$AL$5) | AM8: =COUNTIF($B8:$AF8,$AM$5) | AN8: =COUNTIF($B8:$AF8,$AN$5)
AG9: =COUNTIF($B9:$AF9,$AG$5) | AH9: =COUNTIF($B9:$AF9,$AH$5) | AI9: =COUNTIF($B9:$AF9,$AI$5) | AJ9: =COUNTIF($B9:$AF9,$AJ$5) | AK9: =COUNTIF($B9:$AF9,$AK$5) | AL9: =COUNTIF($B9:$AF9,$AL$5) | AM9: =COUNTIF($B9:$AF9,$AM$5) | AN9: =COUNTIF($B9:$AF9,$AN$5)
A10: =Jan!A10 | AG10: =COUNTIF($B10:$AF10,$AG$5) | AH10: =COUNTIF($B10:$AF10,$AH$5) | AI10: =COUNTIF($B10:$AF10,$AI$5) | AJ10: =COUNTIF($B10:$AF10,$AJ$5) | AK10: =COUNTIF($B10:$AF10,$AK$5) | AL10: =COUNTIF($B10:$AF10,$AL$5) | AM10: =COUNTIF($B10:$AF10,$AM$5) | AN10: =COUNTIF($B10:$AF10,$AN$5)
AG11: =COUNTIF($B11:$AF11,$AG$5) | AH11: =COUNTIF($B11:$AF11,$AH$5) | AI11: =COUNTIF($B11:$AF11,$AI$5) | AJ11: =COUNTIF($B11:$AF11,$AJ$5) | AK11: =COUNTIF($B11:$AF11,$AK$5) | AL11: =COUNTIF($B11:$AF11,$AL$5) | AM11: =COUNTIF($B11:$AF11,$AM$5) | AN11: =COUNTIF($B11:$AF11,$AN$5)
A12: =Jan!A12 | AG12: =COUNTIF($B12:$AF12,$AG$5) | AH12: =COUNTIF($B12:$AF12,$AH$5) | AI12: =COUNTIF($B12:$AF12,$AI$5) | AJ12: =COUNTIF($B12:$AF12,$AJ$5) | AK12: =COUNTIF($B12:$AF12,$AK$5) | AL12: =COUNTIF($B12:$AF12,$AL$5) | AM12: =COUNTIF($B12:$AF12,$AM$5) | AN12: =COUNTIF($B12:$AF12,$AN$5)
AG13: =COUNTIF($B13:$AF13,$AG$5) | AH13: =COUNTIF($B13:$AF13,$AH$5) | AI13: =COUNTIF($B13:$AF13,$AI$5) | AJ13: =COUNTIF($B13:$AF13,$AJ$5) | AK13: =COUNTIF($B13:$AF13,$AK$5) | AL13: =COUNTIF($B13:$AF13,$AL$5) | AM13: =COUNTIF($B13:$AF13,$AM$5) | AN13: =COUNTIF($B13:$AF13,$AN$5)
A14: =Jan!A14 | AG14: =COUNTIF($B14:$AF14,$AG$5) | AH14: =COUNTIF($B14:$AF14,$AH$5) | AI14: =COUNTIF($B14:$AF14,$AI$5) | AJ14: =COUNTIF($B14:$AF14,$AJ$5) | AK14: =COUNTIF($B14:$AF14,$AK$5) | AL14: =COUNTIF($B14:$AF14,$AL$5) | AM14: =COUNTIF($B14:$AF14,$AM$5) | AN14: =COUNTIF($B14:$AF14,$AN$5)
AG15: =COUNTIF($B15:$AF15,$AG$5) | AH15: =COUNTIF($B15:$AF15,$AH$5) | AI15: =COUNTIF($B15:$AF15,$AI$5) | AJ15: =COUNTIF($B15:$AF15,$AJ$5) | AK15: =COUNTIF($B15:$AF15,$AK$5) | AL15: =COUNTIF($B15:$AF15,$AL$5) | AM15: =COUNTIF($B15:$AF15,$AM$5) | AN15: =COUNTIF($B15:$AF15,$AN$5)
A16: =Jan!A16 | AG16: =COUNTIF($B16:$AF16,$AG$5) | AH16: =COUNTIF($B16:$AF16,$AH$5) | AI16: =COUNTIF($B16:$AF16,$AI$5) | AJ16: =COUNTIF($B16:$AF16,$AJ$5) | AK16: =COUNTIF($B16:$AF16,$AK$5) | AL16: =COUNTIF($B16:$AF16,$AL$5) | AM16: =COUNTIF($B16:$AF16,$AM$5) | AN16: =COUNTIF($B16:$AF16,$AN$5)
AG17: =COUNTIF($B17:$AF17,$AG$5) | AH17: =COUNTIF($B17:$AF17,$AH$5) | AI17: =COUNTIF($B17:$AF17,$AI$5) | AJ17: =COUNTIF($B17:$AF17,$AJ$5) | AK17: =COUNTIF($B17:$AF17,$AK$5) | AL17: =COUNTIF($B17:$AF17,$AL$5) | AM17: =COUNTIF($B17:$AF17,$AM$5) | AN17: =COUNTIF($B17:$AF17,$AN$5)
A18: =Jan!A18 | AG18: =COUNTIF($B18:$AF18,$AG$5) | AH18: =COUNTIF($B18:$AF18,$AH$5) | AI18: =COUNTIF($B18:$AF18,$AI$5) | AJ18: =COUNTIF($B18:$AF18,$AJ$5) | AK18: =COUNTIF($B18:$AF18,$AK$5) | AL18: =COUNTIF($B18:$AF18,$AL$5) | AM18: =COUNTIF($B18:$AF18,$AM$5) | AN18: =COUNTIF($B18:$AF18,$AN$5)
AG19: =COUNTIF($B19:$AF19,$AG$5) | AH19: =COUNTIF($B19:$AF19,$AH$5) | AI19: =COUNTIF($B19:$AF19,$AI$5) | AJ19: =COUNTIF($B19:$AF19,$AJ$5) | AK19: =COUNTIF($B19:$AF19,$AK$5) | AL19: =COUNTIF($B19:$AF19,$AL$5) | AM19: =COUNTIF($B19:$AF19,$AM$5) | AN19: =COUNTIF($B19:$AF19,$AN$5)
A20: =Jan!A20 | AG20: =COUNTIF($B20:$AF20,$AG$5) | AH20: =COUNTIF($B20:$AF20,$AH$5) | AI20: =COUNTIF($B20:$AF20,$AI$5) | AJ20: =COUNTIF($B20:$AF20,$AJ$5) | AK20: =COUNTIF($B20:$AF20,$AK$5) | AL20: =COUNTIF($B20:$AF20,$AL$5) | AM20: =COUNTIF($B20:$AF20,$AM$5) | AN20: =COUNTIF($B20:$AF20,$AN$5)
AG21: =COUNTIF($B21:$AF21,$AG$5) | AH21: =COUNTIF($B21:$AF21,$AH$5) | AI21: =COUNTIF($B21:$AF21,$AI$5) | AJ21: =COUNTIF($B21:$AF21,$AJ$5) | AK21: =COUNTIF($B21:$AF21,$AK$5) | AL21: =COUNTIF($B21:$AF21,$AL$5) | AM21: =COUNTIF($B21:$AF21,$AM$5) | AN21: =COUNTIF($B21:$AF21,$AN$5)
A22: =Jan!A22 | AG22: =COUNTIF($B22:$AF22,$AG$5) | AH22: =COUNTIF($B22:$AF22,$AH$5) | AI22: =COUNTIF($B22:$AF22,$AI$5) | AJ22: =COUNTIF($B22:$AF22,$AJ$5) | AK22: =COUNTIF($B22:$AF22,$AK$5) | AL22: =COUNTIF($B22:$AF22,$AL$5) | AM22: =COUNTIF($B22:$AF22,$AM$5) | AN22: =COUNTIF($B22:$AF22,$AN$5)
AG23: =COUNTIF($B23:$AF23,$AG$5) | AH23: =COUNTIF($B23:$AF23,$AH$5) | AI23: =COUNTIF($B23:$AF23,$AI$5) | AJ23: =COUNTIF($B23:$AF23,$AJ$5) | AK23: =COUNTIF($B23:$AF23,$AK$5) | AL23: =COUNTIF($B23:$AF23,$AL$5) | AM23: =COUNTIF($B23:$AF23,$AM$5) | AN23: =COUNTIF($B23:$AF23,$AN$5)
A24: =Jan!A24 | AG24: =COUNTIF($B24:$AF24,$AG$5) | AH24: =COUNTIF($B24:$AF24,$AH$5) | AI24: =COUNTIF($B24:$AF24,$AI$5) | AJ24: =COUNTIF($B24:$AF24,$AJ$5) | AK24: =COUNTIF($B24:$AF24,$AK$5) | AL24: =COUNTIF($B24:$AF24,$AL$5) | AM24: =COUNTIF($B24:$AF24,$AM$5) | AN24: =COUNTIF($B24:$AF24,$AN$5)
AG25: =COUNTIF($B25:$AF25,$AG$5) | AH25: =COUNTIF($B25:$AF25,$AH$5) | AI25: =COUNTIF($B25:$AF25,$AI$5) | AJ25: =COUNTIF($B25:$AF25,$AJ$5) | AK25: =COUNTIF($B25:$AF25,$AK$5) | AL25: =COUNTIF($B25:$AF25,$AL$5) | AM25: =COUNTIF($B25:$AF25,$AM$5) | AN25: =COUNTIF($B25:$AF25,$AN$5)
A26: =Jan!A26 | AG26: =COUNTIF($B26:$AF26,$AG$5) | AH26: =COUNTIF($B26:$AF26,$AH$5) | AI26: =COUNTIF($B26:$AF26,$AI$5) | AJ26: =COUNTIF($B26:$AF26,$AJ$5) | AK26: =COUNTIF($B26:$AF26,$AK$5) | AL26: =COUNTIF($B26:$AF26,$AL$5) | AM26: =COUNTIF($B26:$AF26,$AM$5) | AN26: =COUNTIF($B26:$AF26,$AN$5)
AG27: =COUNTIF($B27:$AF27,$AG$5) | AH27: =COUNTIF($B27:$AF27,$AH$5) | AI27: =COUNTIF($B27:$AF27,$AI$5) | AJ27: =COUNTIF($B27:$AF27,$AJ$5) | AK27: =COUNTIF($B27:$AF27,$AK$5) | AL27: =COUNTIF($B27:$AF27,$AL$5) | AM27: =COUNTIF($B27:$AF27,$AM$5) | AN27: =COUNTIF($B27:$AF27,$AN$5)
A28: =Jan!A28 | AG28: =COUNTIF($B28:$AF28,$AG$5) | AH28: =COUNTIF($B28:$AF28,$AH$5) | AI28: =COUNTIF($B28:$AF28,$AI$5) | AJ28: =COUNTIF($B28:$AF28,$AJ$5) | AK28: =COUNTIF($B28:$AF28,$AK$5) | AL28: =COUNTIF($B28:$AF28,$AL$5) | AM28: =COUNTIF($B28:$AF28,$AM$5) | AN28: =COUNTIF($B28:$AF28,$AN$5)
AG29: =COUNTIF($B29:$AF29,$AG$5) | AH29: =COUNTIF($B29:$AF29,$AH$5) | AI29: =COUNTIF($B29:$AF29,$AI$5) | AJ29: =COUNTIF($B29:$AF29,$AJ$5) | AK29: =COUNTIF($B29:$AF29,$AK$5) | AL29: =COUNTIF($B29:$AF29,$AL$5) | AM29: =COUNTIF($B29:$AF29,$AM$5) | AN29: =COUNTIF($B29:$AF29,$AN$5)
A30: =Jan!A30 | AG30: =COUNTIF($B30:$AF30,$AG$5) | AH30: =COUNTIF($B30:$AF30,$AH$5) | AI30: =COUNTIF($B30:$AF30,$AI$5) | AJ30: =COUNTIF($B30:$AF30,$AJ$5) | AK30: =COUNTIF($B30:$AF30,$AK$5) | AL30: =COUNTIF($B30:$AF30,$AL$5) | AM30: =COUNTIF($B30:$AF30,$AM$5) | AN30: =COUNTIF($B30:$AF30,$AN$5)
AG31: =COUNTIF($B31:$AF31,$AG$5) | AH31: =COUNTIF($B31:$AF31,$AH$5) | AI31: =COUNTIF($B31:$AF31,$AI$5) | AJ31: =COUNTIF($B31:$AF31,$AJ$5) | AK31: =COUNTIF($B31:$AF31,$AK$5) | AL31: =COUNTIF($B31:$AF31,$AL$5) | AM31: =COUNTIF($B31:$AF31,$AM$5) | AN31: =COUNTIF($B31:$AF31,$AN$5)
A32: =Jan!A32 | AG32: =COUNTIF($B32:$AF32,$AG$5) | AH32: =COUNTIF($B32:$AF32,$AH$5) | AI32: =COUNTIF($B32:$AF32,$AI$5) | AJ32: =COUNTIF($B32:$AF32,$AJ$5) | AK32: =COUNTIF($B32:$AF32,$AK$5) | AL32: =COUNTIF($B32:$AF32,$AL$5) | AM32: =COUNTIF($B32:$AF32,$AM$5) | AN32: =COUNTIF($B32:$AF32,$AN$5)
AG33: =COUNTIF($B33:$AF33,$AG$5) | AH33: =COUNTIF($B33:$AF33,$AH$5) | AI33: =COUNTIF($B33:$AF33,$AI$5) | AJ33: =COUNTIF($B33:$AF33,$AJ$5) | AK33: =COUNTIF($B33:$AF33,$AK$5) | AL33: =COUNTIF($B33:$AF33,$AL$5) | AM33: =COUNTIF($B33:$AF33,$AM$5) | AN33: =COUNTIF($B33:$AF33,$AN$5)
A34: =Jan!A34 | AG34: =COUNTIF($B34:$AF34,$AG$5) | AH34: =COUNTIF($B34:$AF34,$AH$5) | AI34: =COUNTIF($B34:$AF34,$AI$5) | AJ34: =COUNTIF($B34:$AF34,$AJ$5) | AK34: =COUNTIF($B34:$AF34,$AK$5) | AL34: =COUNTIF($B34:$AF34,$AL$5) | AM34: =COUNTIF($B34:$AF34,$AM$5) | AN34: =COUNTIF($B34:$AF34,$AN$5)
AG35: =COUNTIF($B35:$AF35,$AG$5) | AH35: =COUNTIF($B35:$AF35,$AH$5) | AI35: =COUNTIF($B35:$AF35,$AI$5) | AJ35: =COUNTIF($B35:$AF35,$AJ$5) | AK35: =COUNTIF($B35:$AF35,$AK$5) | AL35: =COUNTIF($B35:$AF35,$AL$5) | AM35: =COUNTIF($B35:$AF35,$AM$5) | AN35: =COUNTIF($B35:$AF35,$AN$5)
A36: =Jan!A36 | AG36: =COUNTIF($B36:$AF36,$AG$5) | AH36: =COUNTIF($B36:$AF36,$AH$5) | AI36: =COUNTIF($B36:$AF36,$AI$5) | AJ36: =COUNTIF($B36:$AF36,$AJ$5) | AK36: =COUNTIF($B36:$AF36,$AK$5) | AL36: =COUNTIF($B36:$AF36,$AL$5) | AM36: =COUNTIF($B36:$AF36,$AM$5) | AN36: =COUNTIF($B36:$AF36,$AN$5)
AG37: =COUNTIF($B37:$AF37,$AG$5) | AH37: =COUNTIF($B37:$AF37,$AH$5) | AI37: =COUNTIF($B37:$AF37,$AI$5) | AJ37: =COUNTIF($B37:$AF37,$AJ$5) | AK37: =COUNTIF($B37:$AF37,$AK$5) | AL37: =COUNTIF($B37:$AF37,$AL$5) | AM37: =COUNTIF($B37:$AF37,$AM$5) | AN37: =COUNTIF($B37:$AF37,$AN$5)
A38: =Jan!A38 | AG38: =COUNTIF($B38:$AF38,$AG$5) | AH38: =COUNTIF($B38:$AF38,$AH$5) | AI38: =COUNTIF($B38:$AF38,$AI$5) | AJ38: =COUNTIF($B38:$AF38,$AJ$5) | AK38: =COUNTIF($B38:$AF38,$AK$5) | AL38: =COUNTIF($B38:$AF38,$AL$5) | AM38: =COUNTIF($B38:$AF38,$AM$5) | AN38: =COUNTIF($B38:$AF38,$AN$5)
AG39: =COUNTIF($B39:$AF39,$AG$5) | AH39: =COUNTIF($B39:$AF39,$AH$5) | AI39: =COUNTIF($B39:$AF39,$AI$5) | AJ39: =COUNTIF($B39:$AF39,$AJ$5) | AK39: =COUNTIF($B39:$AF39,$AK$5) | AL39: =COUNTIF($B39:$AF39,$AL$5) | AM39: =COUNTIF($B39:$AF39,$AM$5) | AN39: =COUNTIF($B39:$AF39,$AN$5)
A40: =Jan!A40 | AG40: =COUNTIF($B40:$AF40,$AG$5) | AH40: =COUNTIF($B40:$AF40,$AH$5) | AI40: =COUNTIF($B40:$AF40,$AI$5) | AJ40: =COUNTIF($B40:$AF40,$AJ$5) | AK40: =COUNTIF($B40:$AF40,$AK$5) | AL40: =COUNTIF($B40:$AF40,$AL$5) | AM40: =COUNTIF($B40:$AF40,$AM$5) | AN40: =COUNTIF($B40:$AF40,$AN$5)
AG41: =COUNTIF($B41:$AF41,$AG$5) | AH41: =COUNTIF($B41:$AF41,$AH$5) | AI41: =COUNTIF($B41:$AF41,$AI$5) | AJ41: =COUNTIF($B41:$AF41,$AJ$5) | AK41: =COUNTIF($B41:$AF41,$AK$5) | AL41: =COUNTIF($B41:$AF41,$AL$5) | AM41: =COUNTIF($B41:$AF41,$AM$5) | AN41: =COUNTIF($B41:$AF41,$AN$5)
...

Sheet Mar
A1: PREASONT REPORT IN THE MONTH OF MAR 2015
A3: A - ABSENT | B3: L - LEAVE | F3: WO - WEEKLY OFF | K3: PH - PUBLIC HOLIDAY | P3: CO - COMP. OFF | U3: ML - MEDICAL. LEAVE | AA3: ODK - WORK AT KARAI
B4: CALENDER DATES
A5: NAME | B5: 1 | C5: 2 | D5: 3 | E5: 4 | F5: 5 | G5: 6 | H5: 7 | I5: 8 | J5: 9 | K5: 10 | L5: 11 | M5: 12 | N5: 13 | O5: 14 | P5: 15 | Q5: 16 | R5: 17 | S5: 18 | T5: 19 | U5: 20 | V5: 21 | W5: 22 | X5: 23 | Y5: 24 | Z5: 25 | AA5: 26 | AB5: 27 | AC5: 28 | AD5: 29 | AE5: 30 | AF5: 31 | AG5: P | AH5: ODK | AI5: A | AJ5: L | AK5: WO | AL5: PH | AM5: CO | AN5: ML | AO5: REMARKS
A6: =Jan!A6 | AG6: =COUNTIF($B6:$AF6,$AG$5) | AH6: =COUNTIF($B6:$AF6,$AH$5) | AI6: =COUNTIF($B6:$AF6,$AI$5) | AJ6: =COUNTIF($B6:$AF6,$AJ$5) | AK6: =COUNTIF($B6:$AF6,$AK$5) | AL6: =COUNTIF($B6:$AF6,$AL$5) | AM6: =COUNTIF($B6:$AF6,$AM$5) | AN6: =COUNTIF($B6:$AF6,$AN$5) | AO6: 1 COM-OFF
AG7: =COUNTIF($B7:$AF7,$AG$5) | AH7: =COUNTIF($B7:$AF7,$AH$5) | AI7: =COUNTIF($B7:$AF7,$AI$5) | AJ7: =COUNTIF($B7:$AF7,$AJ$5) | AK7: =COUNTIF($B7:$AF7,$AK$5) | AL7: =COUNTIF($B7:$AF7,$AL$5) | AM7: =COUNTIF($B7:$AF7,$AM$5) | AN7: =COUNTIF($B7:$AF7,$AN$5)
A8: =Jan!A8 | AG8: =COUNTIF($B8:$AF8,$AG$5) | AH8: =COUNTIF($B8:$AF8,$AH$5) | AI8: =COUNTIF($B8:$AF8,$AI$5) | AJ8: =COUNTIF($B8:$AF8,$AJ$5) | AK8: =COUNTIF($B8:$AF8,$AK$5) | AL8: =COUNTIF($B8:$AF8,$AL$5) | AM8: =COUNTIF($B8:$AF8,$AM$5) | AN8: =COUNTIF($B8:$AF8,$AN$5)
AG9: =COUNTIF($B9:$AF9,$AG$5) | AH9: =COUNTIF($B9:$AF9,$AH$5) | AI9: =COUNTIF($B9:$AF9,$AI$5) | AJ9: =COUNTIF($B9:$AF9,$AJ$5) | AK9: =COUNTIF($B9:$AF9,$AK$5) | AL9: =COUNTIF($B9:$AF9,$AL$5) | AM9: =COUNTIF($B9:$AF9,$AM$5) | AN9: =COUNTIF($B9:$AF9,$AN$5)
A10: =Jan!A10 | AG10: =COUNTIF($B10:$AF10,$AG$5) | AH10: =COUNTIF($B10:$AF10,$AH$5) | AI10: =COUNTIF($B10:$AF10,$AI$5) | AJ10: =COUNTIF($B10:$AF10,$AJ$5) | AK10: =COUNTIF($B10:$AF10,$AK$5) | AL10: =COUNTIF($B10:$AF10,$AL$5) | AM10: =COUNTIF($B10:$AF10,$AM$5) | AN10: =COUNTIF($B10:$AF10,$AN$5)
AG11: =COUNTIF($B11:$AF11,$AG$5) | AH11: =COUNTIF($B11:$AF11,$AH$5) | AI11: =COUNTIF($B11:$AF11,$AI$5) | AJ11: =COUNTIF($B11:$AF11,$AJ$5) | AK11: =COUNTIF($B11:$AF11,$AK$5) | AL11: =COUNTIF($B11:$AF11,$AL$5) | AM11: =COUNTIF($B11:$AF11,$AM$5) | AN11: =COUNTIF($B11:$AF11,$AN$5)
A12: =Jan!A12 | AG12: =COUNTIF($B12:$AF12,$AG$5) | AH12: =COUNTIF($B12:$AF12,$AH$5) | AI12: =COUNTIF($B12:$AF12,$AI$5) | AJ12: =COUNTIF($B12:$AF12,$AJ$5) | AK12: =COUNTIF($B12:$AF12,$AK$5) | AL12: =COUNTIF($B12:$AF12,$AL$5) | AM12: =COUNTIF($B12:$AF12,$AM$5) | AN12: =COUNTIF($B12:$AF12,$AN$5)
AG13: =COUNTIF($B13:$AF13,$AG$5) | AH13: =COUNTIF($B13:$AF13,$AH$5) | AI13: =COUNTIF($B13:$AF13,$AI$5) | AJ13: =COUNTIF($B13:$AF13,$AJ$5) | AK13: =COUNTIF($B13:$AF13,$AK$5) | AL13: =COUNTIF($B13:$AF13,$AL$5) | AM13: =COUNTIF($B13:$AF13,$AM$5) | AN13: =COUNTIF($B13:$AF13,$AN$5)
A14: =Jan!A14 | AG14: =COUNTIF($B14:$AF14,$AG$5) | AH14: =COUNTIF($B14:$AF14,$AH$5) | AI14: =COUNTIF($B14:$AF14,$AI$5) | AJ14: =COUNTIF($B14:$AF14,$AJ$5) | AK14: =COUNTIF($B14:$AF14,$AK$5) | AL14: =COUNTIF($B14:$AF14,$AL$5) | AM14: =COUNTIF($B14:$AF14,$AM$5) | AN14: =COUNTIF($B14:$AF14,$AN$5)
AG15: =COUNTIF($B15:$AF15,$AG$5) | AH15: =COUNTIF($B15:$AF15,$AH$5) | AI15: =COUNTIF($B15:$AF15,$AI$5) | AJ15: =COUNTIF($B15:$AF15,$AJ$5) | AK15: =COUNTIF($B15:$AF15,$AK$5) | AL15: =COUNTIF($B15:$AF15,$AL$5) | AM15: =COUNTIF($B15:$AF15,$AM$5) | AN15: =COUNTIF($B15:$AF15,$AN$5)
A16: =Jan!A16 | AG16: =COUNTIF($B16:$AF16,$AG$5) | AH16: =COUNTIF($B16:$AF16,$AH$5) | AI16: =COUNTIF($B16:$AF16,$AI$5) | AJ16: =COUNTIF($B16:$AF16,$AJ$5) | AK16: =COUNTIF($B16:$AF16,$AK$5) | AL16: =COUNTIF($B16:$AF16,$AL$5) | AM16: =COUNTIF($B16:$AF16,$AM$5) | AN16: =COUNTIF($B16:$AF16,$AN$5)
AG17: =COUNTIF($B17:$AF17,$AG$5) | AH17: =COUNTIF($B17:$AF17,$AH$5) | AI17: =COUNTIF($B17:$AF17,$AI$5) | AJ17: =COUNTIF($B17:$AF17,$AJ$5) | AK17: =COUNTIF($B17:$AF17,$AK$5) | AL17: =COUNTIF($B17:$AF17,$AL$5) | AM17: =COUNTIF($B17:$AF17,$AM$5) | AN17: =COUNTIF($B17:$AF17,$AN$5)
A18: =Jan!A18 | AG18: =COUNTIF($B18:$AF18,$AG$5) | AH18: =COUNTIF($B18:$AF18,$AH$5) | AI18: =COUNTIF($B18:$AF18,$AI$5) | AJ18: =COUNTIF($B18:$AF18,$AJ$5) | AK18: =COUNTIF($B18:$AF18,$AK$5) | AL18: =COUNTIF($B18:$AF18,$AL$5) | AM18: =COUNTIF($B18:$AF18,$AM$5) | AN18: =COUNTIF($B18:$AF18,$AN$5)
AG19: =COUNTIF($B19:$AF19,$AG$5) | AH19: =COUNTIF($B19:$AF19,$AH$5) | AI19: =COUNTIF($B19:$AF19,$AI$5) | AJ19: =COUNTIF($B19:$AF19,$AJ$5) | AK19: =COUNTIF($B19:$AF19,$AK$5) | AL19: =COUNTIF($B19:$AF19,$AL$5) | AM19: =COUNTIF($B19:$AF19,$AM$5) | AN19: =COUNTIF($B19:$AF19,$AN$5)
A20: =Jan!A20 | AG20: =COUNTIF($B20:$AF20,$AG$5) | AH20: =COUNTIF($B20:$AF20,$AH$5) | AI20: =COUNTIF($B20:$AF20,$AI$5) | AJ20: =COUNTIF($B20:$AF20,$AJ$5) | AK20: =COUNTIF($B20:$AF20,$AK$5) | AL20: =COUNTIF($B20:$AF20,$AL$5) | AM20: =COUNTIF($B20:$AF20,$AM$5) | AN20: =COUNTIF($B20:$AF20,$AN$5)
AG21: =COUNTIF($B21:$AF21,$AG$5) | AH21: =COUNTIF($B21:$AF21,$AH$5) | AI21: =COUNTIF($B21:$AF21,$AI$5) | AJ21: =COUNTIF($B21:$AF21,$AJ$5) | AK21: =COUNTIF($B21:$AF21,$AK$5) | AL21: =COUNTIF($B21:$AF21,$AL$5) | AM21: =COUNTIF($B21:$AF21,$AM$5) | AN21: =COUNTIF($B21:$AF21,$AN$5)
A22: =Jan!A22 | AG22: =COUNTIF($B22:$AF22,$AG$5) | AH22: =COUNTIF($B22:$AF22,$AH$5) | AI22: =COUNTIF($B22:$AF22,$AI$5) | AJ22: =COUNTIF($B22:$AF22,$AJ$5) | AK22: =COUNTIF($B22:$AF22,$AK$5) | AL22: =COUNTIF($B22:$AF22,$AL$5) | AM22: =COUNTIF($B22:$AF22,$AM$5) | AN22: =COUNTIF($B22:$AF22,$AN$5)
AG23: =COUNTIF($B23:$AF23,$AG$5) | AH23: =COUNTIF($B23:$AF23,$AH$5) | AI23: =COUNTIF($B23:$AF23,$AI$5) | AJ23: =COUNTIF($B23:$AF23,$AJ$5) | AK23: =COUNTIF($B23:$AF23,$AK$5) | AL23: =COUNTIF($B23:$AF23,$AL$5) | AM23: =COUNTIF($B23:$AF23,$AM$5) | AN23: =COUNTIF($B23:$AF23,$AN$5)
A24: =Jan!A24 | AG24: =COUNTIF($B24:$AF24,$AG$5) | AH24: =COUNTIF($B24:$AF24,$AH$5) | AI24: =COUNTIF($B24:$AF24,$AI$5) | AJ24: =COUNTIF($B24:$AF24,$AJ$5) | AK24: =COUNTIF($B24:$AF24,$AK$5) | AL24: =COUNTIF($B24:$AF24,$AL$5) | AM24: =COUNTIF($B24:$AF24,$AM$5) | AN24: =COUNTIF($B24:$AF24,$AN$5)
AG25: =COUNTIF($B25:$AF25,$AG$5) | AH25: =COUNTIF($B25:$AF25,$AH$5) | AI25: =COUNTIF($B25:$AF25,$AI$5) | AJ25: =COUNTIF($B25:$AF25,$AJ$5) | AK25: =COUNTIF($B25:$AF25,$AK$5) | AL25: =COUNTIF($B25:$AF25,$AL$5) | AM25: =COUNTIF($B25:$AF25,$AM$5) | AN25: =COUNTIF($B25:$AF25,$AN$5)
A26: =Jan!A26 | AG26: =COUNTIF($B26:$AF26,$AG$5) | AH26: =COUNTIF($B26:$AF26,$AH$5) | AI26: =COUNTIF($B26:$AF26,$AI$5) | AJ26: =COUNTIF($B26:$AF26,$AJ$5) | AK26: =COUNTIF($B26:$AF26,$AK$5) | AL26: =COUNTIF($B26:$AF26,$AL$5) | AM26: =COUNTIF($B26:$AF26,$AM$5) | AN26: =COUNTIF($B26:$AF26,$AN$5)
AG27: =COUNTIF($B27:$AF27,$AG$5) | AH27: =COUNTIF($B27:$AF27,$AH$5) | AI27: =COUNTIF($B27:$AF27,$AI$5) | AJ27: =COUNTIF($B27:$AF27,$AJ$5) | AK27: =COUNTIF($B27:$AF27,$AK$5) | AL27: =COUNTIF($B27:$AF27,$AL$5) | AM27: =COUNTIF($B27:$AF27,$AM$5) | AN27: =COUNTIF($B27:$AF27,$AN$5)
A28: =Jan!A28 | AG28: =COUNTIF($B28:$AF28,$AG$5) | AH28: =COUNTIF($B28:$AF28,$AH$5) | AI28: =COUNTIF($B28:$AF28,$AI$5) | AJ28: =COUNTIF($B28:$AF28,$AJ$5) | AK28: =COUNTIF($B28:$AF28,$AK$5) | AL28: =COUNTIF($B28:$AF28,$AL$5) | AM28: =COUNTIF($B28:$AF28,$AM$5) | AN28: =COUNTIF($B28:$AF28,$AN$5)
AG29: =COUNTIF($B29:$AF29,$AG$5) | AH29: =COUNTIF($B29:$AF29,$AH$5) | AI29: =COUNTIF($B29:$AF29,$AI$5) | AJ29: =COUNTIF($B29:$AF29,$AJ$5) | AK29: =COUNTIF($B29:$AF29,$AK$5) | AL29: =COUNTIF($B29:$AF29,$AL$5) | AM29: =COUNTIF($B29:$AF29,$AM$5) | AN29: =COUNTIF($B29:$AF29,$AN$5)
A30: =Jan!A30 | AG30: =COUNTIF($B30:$AF30,$AG$5) | AH30: =COUNTIF($B30:$AF30,$AH$5) | AI30: =COUNTIF($B30:$AF30,$AI$5) | AJ30: =COUNTIF($B30:$AF30,$AJ$5) | AK30: =COUNTIF($B30:$AF30,$AK$5) | AL30: =COUNTIF($B30:$AF30,$AL$5) | AM30: =COUNTIF($B30:$AF30,$AM$5) | AN30: =COUNTIF($B30:$AF30,$AN$5)
AG31: =COUNTIF($B31:$AF31,$AG$5) | AH31: =COUNTIF($B31:$AF31,$AH$5) | AI31: =COUNTIF($B31:$AF31,$AI$5) | AJ31: =COUNTIF($B31:$AF31,$AJ$5) | AK31: =COUNTIF($B31:$AF31,$AK$5) | AL31: =COUNTIF($B31:$AF31,$AL$5) | AM31: =COUNTIF($B31:$AF31,$AM$5) | AN31: =COUNTIF($B31:$AF31,$AN$5)
A32: =Jan!A32 | AG32: =COUNTIF($B32:$AF32,$AG$5) | AH32: =COUNTIF($B32:$AF32,$AH$5) | AI32: =COUNTIF($B32:$AF32,$AI$5) | AJ32: =COUNTIF($B32:$AF32,$AJ$5) | AK32: =COUNTIF($B32:$AF32,$AK$5) | AL32: =COUNTIF($B32:$AF32,$AL$5) | AM32: =COUNTIF($B32:$AF32,$AM$5) | AN32: =COUNTIF($B32:$AF32,$AN$5)
AG33: =COUNTIF($B33:$AF33,$AG$5) | AH33: =COUNTIF($B33:$AF33,$AH$5) | AI33: =COUNTIF($B33:$AF33,$AI$5) | AJ33: =COUNTIF($B33:$AF33,$AJ$5) | AK33: =COUNTIF($B33:$AF33,$AK$5) | AL33: =COUNTIF($B33:$AF33,$AL$5) | AM33: =COUNTIF($B33:$AF33,$AM$5) | AN33: =COUNTIF($B33:$AF33,$AN$5)
A34: =Jan!A34 | AG34: =COUNTIF($B34:$AF34,$AG$5) | AH34: =COUNTIF($B34:$AF34,$AH$5) | AI34: =COUNTIF($B34:$AF34,$AI$5) | AJ34: =COUNTIF($B34:$AF34,$AJ$5) | AK34: =COUNTIF($B34:$AF34,$AK$5) | AL34: =COUNTIF($B34:$AF34,$AL$5) | AM34: =COUNTIF($B34:$AF34,$AM$5) | AN34: =COUNTIF($B34:$AF34,$AN$5)
AG35: =COUNTIF($B35:$AF35,$AG$5) | AH35: =COUNTIF($B35:$AF35,$AH$5) | AI35: =COUNTIF($B35:$AF35,$AI$5) | AJ35: =COUNTIF($B35:$AF35,$AJ$5) | AK35: =COUNTIF($B35:$AF35,$AK$5) | AL35: =COUNTIF($B35:$AF35,$AL$5) | AM35: =COUNTIF($B35:$AF35,$AM$5) | AN35: =COUNTIF($B35:$AF35,$AN$5)
A36: =Jan!A36 | AG36: =COUNTIF($B36:$AF36,$AG$5) | AH36: =COUNTIF($B36:$AF36,$AH$5) | AI36: =COUNTIF($B36:$AF36,$AI$5) | AJ36: =COUNTIF($B36:$AF36,$AJ$5) | AK36: =COUNTIF($B36:$AF36,$AK$5) | AL36: =COUNTIF($B36:$AF36,$AL$5) | AM36: =COUNTIF($B36:$AF36,$AM$5) | AN36: =COUNTIF($B36:$AF36,$AN$5)
AG37: =COUNTIF($B37:$AF37,$AG$5) | AH37: =COUNTIF($B37:$AF37,$AH$5) | AI37: =COUNTIF($B37:$AF37,$AI$5) | AJ37: =COUNTIF($B37:$AF37,$AJ$5) | AK37: =COUNTIF($B37:$AF37,$AK$5) | AL37: =COUNTIF($B37:$AF37,$AL$5) | AM37: =COUNTIF($B37:$AF37,$AM$5) | AN37: =COUNTIF($B37:$AF37,$AN$5)
A38: =Jan!A38 | AG38: =COUNTIF($B38:$AF38,$AG$5) | AH38: =COUNTIF($B38:$AF38,$AH$5) | AI38: =COUNTIF($B38:$AF38,$AI$5) | AJ38: =COUNTIF($B38:$AF38,$AJ$5) | AK38: =COUNTIF($B38:$AF38,$AK$5) | AL38: =COUNTIF($B38:$AF38,$AL$5) | AM38: =COUNTIF($B38:$AF38,$AM$5) | AN38: =COUNTIF($B38:$AF38,$AN$5)
AG39: =COUNTIF($B39:$AF39,$AG$5) | AH39: =COUNTIF($B39:$AF39,$AH$5) | AI39: =COUNTIF($B39:$AF39,$AI$5) | AJ39: =COUNTIF($B39:$AF39,$AJ$5) | AK39: =COUNTIF($B39:$AF39,$AK$5) | AL39: =COUNTIF($B39:$AF39,$AL$5) | AM39: =COUNTIF($B39:$AF39,$AM$5) | AN39: =COUNTIF($B39:$AF39,$AN$5)
A40: =Jan!A40 | AG40: =COUNTIF($B40:$AF40,$AG$5) | AH40: =COUNTIF($B40:$AF40,$AH$5) | AI40: =COUNTIF($B40:$AF40,$AI$5) | AJ40: =COUNTIF($B40:$AF40,$AJ$5) | AK40: =COUNTIF($B40:$AF40,$AK$5) | AL40: =COUNTIF($B40:$AF40,$AL$5) | AM40: =COUNTIF($B40:$AF40,$AM$5) | AN40: =COUNTIF($B40:$AF40,$AN$5)
AG41: =COUNTIF($B41:$AF41,$AG$5) | AH41: =COUNTIF($B41:$AF41,$AH$5) | AI41: =COUNTIF($B41:$AF41,$AI$5) | AJ41: =COUNTIF($B41:$AF41,$AJ$5) | AK41: =COUNTIF($B41:$AF41,$AK$5) | AL41: =COUNTIF($B41:$AF41,$AL$5) | AM41: =COUNTIF($B41:$AF41,$AM$5) | AN41: =COUNTIF($B41:$AF41,$AN$5)
...

Sheet Apr
A1: PREASONT REPORT IN THE MONTH OF APR 2015
A3: A - ABSENT | B3: L - LEAVE | F3: WO - WEEKLY OFF | K3: PH - PUBLIC HOLIDAY | P3: CO - COMP. OFF | U3: ML - MEDICAL. LEAVE | AA3: ODK - WORK AT KARAI
B4: CALENDER DATES
A5: NAME | B5: 1 | C5: 2 | D5: 3 | E5: 4 | F5: 5 | G5: 6 | H5: 7 | I5: 8 | J5: 9 | K5: 10 | L5: 11 | M5: 12 | N5: 13 | O5: 14 | P5: 15 | Q5: 16 | R5: 17 | S5: 18 | T5: 19 | U5: 20 | V5: 21 | W5: 22 | X5: 23 | Y5: 24 | Z5: 25 | AA5: 26 | AB5: 27 | AC5: 28 | AD5: 29 | AE5: 30 | AF5: 31 | AG5: P | AH5: ODK | AI5: A | AJ5: L | AK5: WO | AL5: PH | AM5: CO | AN5: ML | AO5: REMARKS
A6: =Jan!A6 | AG6: =COUNTIF($B6:$AF6,$AG$5) | AH6: =COUNTIF($B6:$AF6,$AH$5) | AI6: =COUNTIF($B6:$AF6,$AI$5) | AJ6: =COUNTIF($B6:$AF6,$AJ$5) | AK6: =COUNTIF($B6:$AF6,$AK$5) | AL6: =COUNTIF($B6:$AF6,$AL$5) | AM6: =COUNTIF($B6:$AF6,$AM$5) | AN6: =COUNTIF($B6:$AF6,$AN$5) | AO6: 1 COM-OFF
AG7: =COUNTIF($B7:$AF7,$AG$5) | AH7: =COUNTIF($B7:$AF7,$AH$5) | AI7: =COUNTIF($B7:$AF7,$AI$5) | AJ7: =COUNTIF($B7:$AF7,$AJ$5) | AK7: =COUNTIF($B7:$AF7,$AK$5) | AL7: =COUNTIF($B7:$AF7,$AL$5) | AM7: =COUNTIF($B7:$AF7,$AM$5) | AN7: =COUNTIF($B7:$AF7,$AN$5)
A8: =Jan!A8 | AG8: =COUNTIF($B8:$AF8,$AG$5) | AH8: =COUNTIF($B8:$AF8,$AH$5) | AI8: =COUNTIF($B8:$AF8,$AI$5) | AJ8: =COUNTIF($B8:$AF8,$AJ$5) | AK8: =COUNTIF($B8:$AF8,$AK$5) | AL8: =COUNTIF($B8:$AF8,$AL$5) | AM8: =COUNTIF($B8:$AF8,$AM$5) | AN8: =COUNTIF($B8:$AF8,$AN$5)
AG9: =COUNTIF($B9:$AF9,$AG$5) | AH9: =COUNTIF($B9:$AF9,$AH$5) | AI9: =COUNTIF($B9:$AF9,$AI$5) | AJ9: =COUNTIF($B9:$AF9,$AJ$5) | AK9: =COUNTIF($B9:$AF9,$AK$5) | AL9: =COUNTIF($B9:$AF9,$AL$5) | AM9: =COUNTIF($B9:$AF9,$AM$5) | AN9: =COUNTIF($B9:$AF9,$AN$5)
A10: =Jan!A10 | AG10: =COUNTIF($B10:$AF10,$AG$5) | AH10: =COUNTIF($B10:$AF10,$AH$5) | AI10: =COUNTIF($B10:$AF10,$AI$5) | AJ10: =COUNTIF($B10:$AF10,$AJ$5) | AK10: =COUNTIF($B10:$AF10,$AK$5) | AL10: =COUNTIF($B10:$AF10,$AL$5) | AM10: =COUNTIF($B10:$AF10,$AM$5) | AN10: =COUNTIF($B10:$AF10,$AN$5)
AG11: =COUNTIF($B11:$AF11,$AG$5) | AH11: =COUNTIF($B11:$AF11,$AH$5) | AI11: =COUNTIF($B11:$AF11,$AI$5) | AJ11: =COUNTIF($B11:$AF11,$AJ$5) | AK11: =COUNTIF($B11:$AF11,$AK$5) | AL11: =COUNTIF($B11:$AF11,$AL$5) | AM11: =COUNTIF($B11:$AF11,$AM$5) | AN11: =COUNTIF($B11:$AF11,$AN$5)
A12: =Jan!A12 | AG12: =COUNTIF($B12:$AF12,$AG$5) | AH12: =COUNTIF($B12:$AF12,$AH$5) | AI12: =COUNTIF($B12:$AF12,$AI$5) | AJ12: =COUNTIF($B12:$AF12,$AJ$5) | AK12: =COUNTIF($B12:$AF12,$AK$5) | AL12: =COUNTIF($B12:$AF12,$AL$5) | AM12: =COUNTIF($B12:$AF12,$AM$5) | AN12: =COUNTIF($B12:$AF12,$AN$5)
AG13: =COUNTIF($B13:$AF13,$AG$5) | AH13: =COUNTIF($B13:$AF13,$AH$5) | AI13: =COUNTIF($B13:$AF13,$AI$5) | AJ13: =COUNTIF($B13:$AF13,$AJ$5) | AK13: =COUNTIF($B13:$AF13,$AK$5) | AL13: =COUNTIF($B13:$AF13,$AL$5) | AM13: =COUNTIF($B13:$AF13,$AM$5) | AN13: =COUNTIF($B13:$AF13,$AN$5)
A14: =Jan!A14 | AG14: =COUNTIF($B14:$AF14,$AG$5) | AH14: =COUNTIF($B14:$AF14,$AH$5) | AI14: =COUNTIF($B14:$AF14,$AI$5) | AJ14: =COUNTIF($B14:$AF14,$AJ$5) | AK14: =COUNTIF($B14:$AF14,$AK$5) | AL14: =COUNTIF($B14:$AF14,$AL$5) | AM14: =COUNTIF($B14:$AF14,$AM$5) | AN14: =COUNTIF($B14:$AF14,$AN$5)
AG15: =COUNTIF($B15:$AF15,$AG$5) | AH15: =COUNTIF($B15:$AF15,$AH$5) | AI15: =COUNTIF($B15:$AF15,$AI$5) | AJ15: =COUNTIF($B15:$AF15,$AJ$5) | AK15: =COUNTIF($B15:$AF15,$AK$5) | AL15: =COUNTIF($B15:$AF15,$AL$5) | AM15: =COUNTIF($B15:$AF15,$AM$5) | AN15: =COUNTIF($B15:$AF15,$AN$5)
A16: =Jan!A16 | AG16: =COUNTIF($B16:$AF16,$AG$5) | AH16: =COUNTIF($B16:$AF16,$AH$5) | AI16: =COUNTIF($B16:$AF16,$AI$5) | AJ16: =COUNTIF($B16:$AF16,$AJ$5) | AK16: =COUNTIF($B16:$AF16,$AK$5) | AL16: =COUNTIF($B16:$AF16,$AL$5) | AM16: =COUNTIF($B16:$AF16,$AM$5) | AN16: =COUNTIF($B16:$AF16,$AN$5)
AG17: =COUNTIF($B17:$AF17,$AG$5) | AH17: =COUNTIF($B17:$AF17,$AH$5) | AI17: =COUNTIF($B17:$AF17,$AI$5) | AJ17: =COUNTIF($B17:$AF17,$AJ$5) | AK17: =COUNTIF($B17:$AF17,$AK$5) | AL17: =COUNTIF($B17:$AF17,$AL$5) | AM17: =COUNTIF($B17:$AF17,$AM$5) | AN17: =COUNTIF($B17:$AF17,$AN$5)
A18: =Jan!A18 | AG18: =COUNTIF($B18:$AF18,$AG$5) | AH18: =COUNTIF($B18:$AF18,$AH$5) | AI18: =COUNTIF($B18:$AF18,$AI$5) | AJ18: =COUNTIF($B18:$AF18,$AJ$5) | AK18: =COUNTIF($B18:$AF18,$AK$5) | AL18: =COUNTIF($B18:$AF18,$AL$5) | AM18: =COUNTIF($B18:$AF18,$AM$5) | AN18: =COUNTIF($B18:$AF18,$AN$5)
AG19: =COUNTIF($B19:$AF19,$AG$5) | AH19: =COUNTIF($B19:$AF19,$AH$5) | AI19: =COUNTIF($B19:$AF19,$AI$5) | AJ19: =COUNTIF($B19:$AF19,$AJ$5) | AK19: =COUNTIF($B19:$AF19,$AK$5) | AL19: =COUNTIF($B19:$AF19,$AL$5) | AM19: =COUNTIF($B19:$AF19,$AM$5) | AN19: =COUNTIF($B19:$AF19,$AN$5)
A20: =Jan!A20 | AG20: =COUNTIF($B20:$AF20,$AG$5) | AH20: =COUNTIF($B20:$AF20,$AH$5) | AI20: =COUNTIF($B20:$AF20,$AI$5) | AJ20: =COUNTIF($B20:$AF20,$AJ$5) | AK20: =COUNTIF($B20:$AF20,$AK$5) | AL20: =COUNTIF($B20:$AF20,$AL$5) | AM20: =COUNTIF($B20:$AF20,$AM$5) | AN20: =COUNTIF($B20:$AF20,$AN$5)
AG21: =COUNTIF($B21:$AF21,$AG$5) | AH21: =COUNTIF($B21:$AF21,$AH$5) | AI21: =COUNTIF($B21:$AF21,$AI$5) | AJ21: =COUNTIF($B21:$AF21,$AJ$5) | AK21: =COUNTIF($B21:$AF21,$AK$5) | AL21: =COUNTIF($B21:$AF21,$AL$5) | AM21: =COUNTIF($B21:$AF21,$AM$5) | AN21: =COUNTIF($B21:$AF21,$AN$5)
A22: =Jan!A22 | AG22: =COUNTIF($B22:$AF22,$AG$5) | AH22: =COUNTIF($B22:$AF22,$AH$5) | AI22: =COUNTIF($B22:$AF22,$AI$5) | AJ22: =COUNTIF($B22:$AF22,$AJ$5) | AK22: =COUNTIF($B22:$AF22,$AK$5) | AL22: =COUNTIF($B22:$AF22,$AL$5) | AM22: =COUNTIF($B22:$AF22,$AM$5) | AN22: =COUNTIF($B22:$AF22,$AN$5)
AG23: =COUNTIF($B23:$AF23,$AG$5) | AH23: =COUNTIF($B23:$AF23,$AH$5) | AI23: =COUNTIF($B23:$AF23,$AI$5) | AJ23: =COUNTIF($B23:$AF23,$AJ$5) | AK23: =COUNTIF($B23:$AF23,$AK$5) | AL23: =COUNTIF($B23:$AF23,$AL$5) | AM23: =COUNTIF($B23:$AF23,$AM$5) | AN23: =COUNTIF($B23:$AF23,$AN$5)
A24: =Jan!A24 | AG24: =COUNTIF($B24:$AF24,$AG$5) | AH24: =COUNTIF($B24:$AF24,$AH$5) | AI24: =COUNTIF($B24:$AF24,$AI$5) | AJ24: =COUNTIF($B24:$AF24,$AJ$5) | AK24: =COUNTIF($B24:$AF24,$AK$5) | AL24: =COUNTIF($B24:$AF24,$AL$5) | AM24: =COUNTIF($B24:$AF24,$AM$5) | AN24: =COUNTIF($B24:$AF24,$AN$5)
AG25: =COUNTIF($B25:$AF25,$AG$5) | AH25: =COUNTIF($B25:$AF25,$AH$5) | AI25: =COUNTIF($B25:$AF25,$AI$5) | AJ25: =COUNTIF($B25:$AF25,$AJ$5) | AK25: =COUNTIF($B25:$AF25,$AK$5) | AL25: =COUNTIF($B25:$AF25,$AL$5) | AM25: =COUNTIF($B25:$AF25,$AM$5) | AN25: =COUNTIF($B25:$AF25,$AN$5)
A26: =Jan!A26 | AG26: =COUNTIF($B26:$AF26,$AG$5) | AH26: =COUNTIF($B26:$AF26,$AH$5) | AI26: =COUNTIF($B26:$AF26,$AI$5) | AJ26: =COUNTIF($B26:$AF26,$AJ$5) | AK26: =COUNTIF($B26:$AF26,$AK$5) | AL26: =COUNTIF($B26:$AF26,$AL$5) | AM26: =COUNTIF($B26:$AF26,$AM$5) | AN26: =COUNTIF($B26:$AF26,$AN$5)
AG27: =COUNTIF($B27:$AF27,$AG$5) | AH27: =COUNTIF($B27:$AF27,$AH$5) | AI27: =COUNTIF($B27:$AF27,$AI$5) | AJ27: =COUNTIF($B27:$AF27,$AJ$5) | AK27: =COUNTIF($B27:$AF27,$AK$5) | AL27: =COUNTIF($B27:$AF27,$AL$5) | AM27: =COUNTIF($B27:$AF27,$AM$5) | AN27: =COUNTIF($B27:$AF27,$AN$5)
A28: =Jan!A28 | AG28: =COUNTIF($B28:$AF28,$AG$5) | AH28: =COUNTIF($B28:$AF28,$AH$5) | AI28: =COUNTIF($B28:$AF28,$AI$5) | AJ28: =COUNTIF($B28:$AF28,$AJ$5) | AK28: =COUNTIF($B28:$AF28,$AK$5) | AL28: =COUNTIF($B28:$AF28,$AL$5) | AM28: =COUNTIF($B28:$AF28,$AM$5) | AN28: =COUNTIF($B28:$AF28,$AN$5)
AG29: =COUNTIF($B29:$AF29,$AG$5) | AH29: =COUNTIF($B29:$AF29,$AH$5) | AI29: =COUNTIF($B29:$AF29,$AI$5) | AJ29: =COUNTIF($B29:$AF29,$AJ$5) | AK29: =COUNTIF($B29:$AF29,$AK$5) | AL29: =COUNTIF($B29:$AF29,$AL$5) | AM29: =COUNTIF($B29:$AF29,$AM$5) | AN29: =COUNTIF($B29:$AF29,$AN$5)
A30: =Jan!A30 | AG30: =COUNTIF($B30:$AF30,$AG$5) | AH30: =COUNTIF($B30:$AF30,$AH$5) | AI30: =COUNTIF($B30:$AF30,$AI$5) | AJ30: =COUNTIF($B30:$AF30,$AJ$5) | AK30: =COUNTIF($B30:$AF30,$AK$5) | AL30: =COUNTIF($B30:$AF30,$AL$5) | AM30: =COUNTIF($B30:$AF30,$AM$5) | AN30: =COUNTIF($B30:$AF30,$AN$5)
AG31: =COUNTIF($B31:$AF31,$AG$5) | AH31: =COUNTIF($B31:$AF31,$AH$5) | AI31: =COUNTIF($B31:$AF31,$AI$5) | AJ31: =COUNTIF($B31:$AF31,$AJ$5) | AK31: =COUNTIF($B31:$AF31,$AK$5) | AL31: =COUNTIF($B31:$AF31,$AL$5) | AM31: =COUNTIF($B31:$AF31,$AM$5) | AN31: =COUNTIF($B31:$AF31,$AN$5)
A32: =Jan!A32 | AG32: =COUNTIF($B32:$AF32,$AG$5) | AH32: =COUNTIF($B32:$AF32,$AH$5) | AI32: =COUNTIF($B32:$AF32,$AI$5) | AJ32: =COUNTIF($B32:$AF32,$AJ$5) | AK32: =COUNTIF($B32:$AF32,$AK$5) | AL32: =COUNTIF($B32:$AF32,$AL$5) | AM32: =COUNTIF($B32:$AF32,$AM$5) | AN32: =COUNTIF($B32:$AF32,$AN$5)
AG33: =COUNTIF($B33:$AF33,$AG$5) | AH33: =COUNTIF($B33:$AF33,$AH$5) | AI33: =COUNTIF($B33:$AF33,$AI$5) | AJ33: =COUNTIF($B33:$AF33,$AJ$5) | AK33: =COUNTIF($B33:$AF33,$AK$5) | AL33: =COUNTIF($B33:$AF33,$AL$5) | AM33: =COUNTIF($B33:$AF33,$AM$5) | AN33: =COUNTIF($B33:$AF33,$AN$5)
A34: =Jan!A34 | AG34: =COUNTIF($B34:$AF34,$AG$5) | AH34: =COUNTIF($B34:$AF34,$AH$5) | AI34: =COUNTIF($B34:$AF34,$AI$5) | AJ34: =COUNTIF($B34:$AF34,$AJ$5) | AK34: =COUNTIF($B34:$AF34,$AK$5) | AL34: =COUNTIF($B34:$AF34,$AL$5) | AM34: =COUNTIF($B34:$AF34,$AM$5) | AN34: =COUNTIF($B34:$AF34,$AN$5)
AG35: =COUNTIF($B35:$AF35,$AG$5) | AH35: =COUNTIF($B35:$AF35,$AH$5) | AI35: =COUNTIF($B35:$AF35,$AI$5) | AJ35: =COUNTIF($B35:$AF35,$AJ$5) | AK35: =COUNTIF($B35:$AF35,$AK$5) | AL35: =COUNTIF($B35:$AF35,$AL$5) | AM35: =COUNTIF($B35:$AF35,$AM$5) | AN35: =COUNTIF($B35:$AF35,$AN$5)
A36: =Jan!A36 | AG36: =COUNTIF($B36:$AF36,$AG$5) | AH36: =COUNTIF($B36:$AF36,$AH$5) | AI36: =COUNTIF($B36:$AF36,$AI$5) | AJ36: =COUNTIF($B36:$AF36,$AJ$5) | AK36: =COUNTIF($B36:$AF36,$AK$5) | AL36: =COUNTIF($B36:$AF36,$AL$5) | AM36: =COUNTIF($B36:$AF36,$AM$5) | AN36: =COUNTIF($B36:$AF36,$AN$5)
AG37: =COUNTIF($B37:$AF37,$AG$5) | AH37: =COUNTIF($B37:$AF37,$AH$5) | AI37: =COUNTIF($B37:$AF37,$AI$5) | AJ37: =COUNTIF($B37:$AF37,$AJ$5) | AK37: =COUNTIF($B37:$AF37,$AK$5) | AL37: =COUNTIF($B37:$AF37,$AL$5) | AM37: =COUNTIF($B37:$AF37,$AM$5) | AN37: =COUNTIF($B37:$AF37,$AN$5)
A38: =Jan!A38 | AG38: =COUNTIF($B38:$AF38,$AG$5) | AH38: =COUNTIF($B38:$AF38,$AH$5) | AI38: =COUNTIF($B38:$AF38,$AI$5) | AJ38: =COUNTIF($B38:$AF38,$AJ$5) | AK38: =COUNTIF($B38:$AF38,$AK$5) | AL38: =COUNTIF($B38:$AF38,$AL$5) | AM38: =COUNTIF($B38:$AF38,$AM$5) | AN38: =COUNTIF($B38:$AF38,$AN$5)
AG39: =COUNTIF($B39:$AF39,$AG$5) | AH39: =COUNTIF($B39:$AF39,$AH$5) | AI39: =COUNTIF($B39:$AF39,$AI$5) | AJ39: =COUNTIF($B39:$AF39,$AJ$5) | AK39: =COUNTIF($B39:$AF39,$AK$5) | AL39: =COUNTIF($B39:$AF39,$AL$5) | AM39: =COUNTIF($B39:$AF39,$AM$5) | AN39: =COUNTIF($B39:$AF39,$AN$5)
A40: =Jan!A40 | AG40: =COUNTIF($B40:$AF40,$AG$5) | AH40: =COUNTIF($B40:$AF40,$AH$5) | AI40: =COUNTIF($B40:$AF40,$AI$5) | AJ40: =COUNTIF($B40:$AF40,$AJ$5) | AK40: =COUNTIF($B40:$AF40,$AK$5) | AL40: =COUNTIF($B40:$AF40,$AL$5) | AM40: =COUNTIF($B40:$AF40,$AM$5) | AN40: =COUNTIF($B40:$AF40,$AN$5)
AG41: =COUNTIF($B41:$AF41,$AG$5) | AH41: =COUNTIF($B41:$AF41,$AH$5) | AI41: =COUNTIF($B41:$AF41,$AI$5) | AJ41: =COUNTIF($B41:$AF41,$AJ$5) | AK41: =COUNTIF($B41:$AF41,$AK$5) | AL41: =COUNTIF($B41:$AF41,$AL$5) | AM41: =COUNTIF($B41:$AF41,$AM$5) | AN41: =COUNTIF($B41:$AF41,$AN$5)
...

Sheet May
A1: PREASONT REPORT IN THE MONTH OF MAY 2015
A3: A - ABSENT | B3: L - LEAVE | F3: WO - WEEKLY OFF | K3: PH - PUBLIC HOLIDAY | P3: CO - COMP. OFF | U3: ML - MEDICAL. LEAVE | AA3: ODK - WORK AT KARAI
B4: CALENDER DATES
A5: NAME | B5: 1 | C5: 2 | D5: 3 | E5: 4 | F5: 5 | G5: 6 | H5: 7 | I5: 8 | J5: 9 | K5: 10 | L5: 11 | M5: 12 | N5: 13 | O5: 14 | P5: 15 | Q5: 16 | R5: 17 | S5: 18 | T5: 19 | U5: 20 | V5: 21 | W5: 22 | X5: 23 | Y5: 24 | Z5: 25 | AA5: 26 | AB5: 27 | AC5: 28 | AD5: 29 | AE5: 30 | AF5: 31 | AG5: P | AH5: ODK | AI5: A | AJ5: L | AK5: WO | AL5: PH | AM5: CO | AN5: ML | AO5: REMARKS
A6: =Jan!A6 | AG6: =COUNTIF($B6:$AF6,$AG$5) | AH6: =COUNTIF($B6:$AF6,$AH$5) | AI6: =COUNTIF($B6:$AF6,$AI$5) | AJ6: =COUNTIF($B6:$AF6,$AJ$5) | AK6: =COUNTIF($B6:$AF6,$AK$5) | AL6: =COUNTIF($B6:$AF6,$AL$5) | AM6: =COUNTIF($B6:$AF6,$AM$5) | AN6: =COUNTIF($B6:$AF6,$AN$5) | AO6: 1 COM-OFF
AG7: =COUNTIF($B7:$AF7,$AG$5) | AH7: =COUNTIF($B7:$AF7,$AH$5) | AI7: =COUNTIF($B7:$AF7,$AI$5) | AJ7: =COUNTIF($B7:$AF7,$AJ$5) | AK7: =COUNTIF($B7:$AF7,$AK$5) | AL7: =COUNTIF($B7:$AF7,$AL$5) | AM7: =COUNTIF($B7:$AF7,$AM$5) | AN7: =COUNTIF($B7:$AF7,$AN$5)
A8: =Jan!A8 | AG8: =COUNTIF($B8:$AF8,$AG$5) | AH8: =COUNTIF($B8:$AF8,$AH$5) | AI8: =COUNTIF($B8:$AF8,$AI$5) | AJ8: =COUNTIF($B8:$AF8,$AJ$5) | AK8: =COUNTIF($B8:$AF8,$AK$5) | AL8: =COUNTIF($B8:$AF8,$AL$5) | AM8: =COUNTIF($B8:$AF8,$AM$5) | AN8: =COUNTIF($B8:$AF8,$AN$5)
AG9: =COUNTIF($B9:$AF9,$AG$5) | AH9: =COUNTIF($B9:$AF9,$AH$5) | AI9: =COUNTIF($B9:$AF9,$AI$5) | AJ9: =COUNTIF($B9:$AF9,$AJ$5) | AK9: =COUNTIF($B9:$AF9,$AK$5) | AL9: =COUNTIF($B9:$AF9,$AL$5) | AM9: =COUNTIF($B9:$AF9,$AM$5) | AN9: =COUNTIF($B9:$AF9,$AN$5)
A10: =Jan!A10 | AG10: =COUNTIF($B10:$AF10,$AG$5) | AH10: =COUNTIF($B10:$AF10,$AH$5) | AI10: =COUNTIF($B10:$AF10,$AI$5) | AJ10: =COUNTIF($B10:$AF10,$AJ$5) | AK10: =COUNTIF($B10:$AF10,$AK$5) | AL10: =COUNTIF($B10:$AF10,$AL$5) | AM10: =COUNTIF($B10:$AF10,$AM$5) | AN10: =COUNTIF($B10:$AF10,$AN$5)
AG11: =COUNTIF($B11:$AF11,$AG$5) | AH11: =COUNTIF($B11:$AF11,$AH$5) | AI11: =COUNTIF($B11:$AF11,$AI$5) | AJ11: =COUNTIF($B11:$AF11,$AJ$5) | AK11: =COUNTIF($B11:$AF11,$AK$5) | AL11: =COUNTIF($B11:$AF11,$AL$5) | AM11: =COUNTIF($B11:$AF11,$AM$5) | AN11: =COUNTIF($B11:$AF11,$AN$5)
A12: =Jan!A12 | AG12: =COUNTIF($B12:$AF12,$AG$5) | AH12: =COUNTIF($B12:$AF12,$AH$5) | AI12: =COUNTIF($B12:$AF12,$AI$5) | AJ12: =COUNTIF($B12:$AF12,$AJ$5) | AK12: =COUNTIF($B12:$AF12,$AK$5) | AL12: =COUNTIF($B12:$AF12,$AL$5) | AM12: =COUNTIF($B12:$AF12,$AM$5) | AN12: =COUNTIF($B12:$AF12,$AN$5)
AG13: =COUNTIF($B13:$AF13,$AG$5) | AH13: =COUNTIF($B13:$AF13,$AH$5) | AI13: =COUNTIF($B13:$AF13,$AI$5) | AJ13: =COUNTIF($B13:$AF13,$AJ$5) | AK13: =COUNTIF($B13:$AF13,$AK$5) | AL13: =COUNTIF($B13:$AF13,$AL$5) | AM13: =COUNTIF($B13:$AF13,$AM$5) | AN13: =COUNTIF($B13:$AF13,$AN$5)
A14: =Jan!A14 | AG14: =COUNTIF($B14:$AF14,$AG$5) | AH14: =COUNTIF($B14:$AF14,$AH$5) | AI14: =COUNTIF($B14:$AF14,$AI$5) | AJ14: =COUNTIF($B14:$AF14,$AJ$5) | AK14: =COUNTIF($B14:$AF14,$AK$5) | AL14: =COUNTIF($B14:$AF14,$AL$5) | AM14: =COUNTIF($B14:$AF14,$AM$5) | AN14: =COUNTIF($B14:$AF14,$AN$5)
AG15: =COUNTIF($B15:$AF15,$AG$5) | AH15: =COUNTIF($B15:$AF15,$AH$5) | AI15: =COUNTIF($B15:$AF15,$AI$5) | AJ15: =COUNTIF($B15:$AF15,$AJ$5) | AK15: =COUNTIF($B15:$AF15,$AK$5) | AL15: =COUNTIF($B15:$AF15,$AL$5) | AM15: =COUNTIF($B15:$AF15,$AM$5) | AN15: =COUNTIF($B15:$AF15,$AN$5)
A16: =Jan!A16 | AG16: =COUNTIF($B16:$AF16,$AG$5) | AH16: =COUNTIF($B16:$AF16,$AH$5) | AI16: =COUNTIF($B16:$AF16,$AI$5) | AJ16: =COUNTIF($B16:$AF16,$AJ$5) | AK16: =COUNTIF($B16:$AF16,$AK$5) | AL16: =COUNTIF($B16:$AF16,$AL$5) | AM16: =COUNTIF($B16:$AF16,$AM$5) | AN16: =COUNTIF($B16:$AF16,$AN$5)
AG17: =COUNTIF($B17:$AF17,$AG$5) | AH17: =COUNTIF($B17:$AF17,$AH$5) | AI17: =COUNTIF($B17:$AF17,$AI$5) | AJ17: =COUNTIF($B17:$AF17,$AJ$5) | AK17: =COUNTIF($B17:$AF17,$AK$5) | AL17: =COUNTIF($B17:$AF17,$AL$5) | AM17: =COUNTIF($B17:$AF17,$AM$5) | AN17: =COUNTIF($B17:$AF17,$AN$5)
A18: =Jan!A18 | AG18: =COUNTIF($B18:$AF18,$AG$5) | AH18: =COUNTIF($B18:$AF18,$AH$5) | AI18: =COUNTIF($B18:$AF18,$AI$5) | AJ18: =COUNTIF($B18:$AF18,$AJ$5) | AK18: =COUNTIF($B18:$AF18,$AK$5) | AL18: =COUNTIF($B18:$AF18,$AL$5) | AM18: =COUNTIF($B18:$AF18,$AM$5) | AN18: =COUNTIF($B18:$AF18,$AN$5)
AG19: =COUNTIF($B19:$AF19,$AG$5) | AH19: =COUNTIF($B19:$AF19,$AH$5) | AI19: =COUNTIF($B19:$AF19,$AI$5) | AJ19: =COUNTIF($B19:$AF19,$AJ$5) | AK19: =COUNTIF($B19:$AF19,$AK$5) | AL19: =COUNTIF($B19:$AF19,$AL$5) | AM19: =COUNTIF($B19:$AF19,$AM$5) | AN19: =COUNTIF($B19:$AF19,$AN$5)
A20: =Jan!A20 | AG20: =COUNTIF($B20:$AF20,$AG$5) | AH20: =COUNTIF($B20:$AF20,$AH$5) | AI20: =COUNTIF($B20:$AF20,$AI$5) | AJ20: =COUNTIF($B20:$AF20,$AJ$5) | AK20: =COUNTIF($B20:$AF20,$AK$5) | AL20: =COUNTIF($B20:$AF20,$AL$5) | AM20: =COUNTIF($B20:$AF20,$AM$5) | AN20: =COUNTIF($B20:$AF20,$AN$5)
AG21: =COUNTIF($B21:$AF21,$AG$5) | AH21: =COUNTIF($B21:$AF21,$AH$5) | AI21: =COUNTIF($B21:$AF21,$AI$5) | AJ21: =COUNTIF($B21:$AF21,$AJ$5) | AK21: =COUNTIF($B21:$AF21,$AK$5) | AL21: =COUNTIF($B21:$AF21,$AL$5) | AM21: =COUNTIF($B21:$AF21,$AM$5) | AN21: =COUNTIF($B21:$AF21,$AN$5)
A22: =Jan!A22 | AG22: =COUNTIF($B22:$AF22,$AG$5) | AH22: =COUNTIF($B22:$AF22,$AH$5) | AI22: =COUNTIF($B22:$AF22,$AI$5) | AJ22: =COUNTIF($B22:$AF22,$AJ$5) | AK22: =COUNTIF($B22:$AF22,$AK$5) | AL22: =COUNTIF($B22:$AF22,$AL$5) | AM22: =COUNTIF($B22:$AF22,$AM$5) | AN22: =COUNTIF($B22:$AF22,$AN$5)
AG23: =COUNTIF($B23:$AF23,$AG$5) | AH23: =COUNTIF($B23:$AF23,$AH$5) | AI23: =COUNTIF($B23:$AF23,$AI$5) | AJ23: =COUNTIF($B23:$AF23,$AJ$5) | AK23: =COUNTIF($B23:$AF23,$AK$5) | AL23: =COUNTIF($B23:$AF23,$AL$5) | AM23: =COUNTIF($B23:$AF23,$AM$5) | AN23: =COUNTIF($B23:$AF23,$AN$5)
A24: =Jan!A24 | AG24: =COUNTIF($B24:$AF24,$AG$5) | AH24: =COUNTIF($B24:$AF24,$AH$5) | AI24: =COUNTIF($B24:$AF24,$AI$5) | AJ24: =COUNTIF($B24:$AF24,$AJ$5) | AK24: =COUNTIF($B24:$AF24,$AK$5) | AL24: =COUNTIF($B24:$AF24,$AL$5) | AM24: =COUNTIF($B24:$AF24,$AM$5) | AN24: =COUNTIF($B24:$AF24,$AN$5)
AG25: =COUNTIF($B25:$AF25,$AG$5) | AH25: =COUNTIF($B25:$AF25,$AH$5) | AI25: =COUNTIF($B25:$AF25,$AI$5) | AJ25: =COUNTIF($B25:$AF25,$AJ$5) | AK25: =COUNTIF($B25:$AF25,$AK$5) | AL25: =COUNTIF($B25:$AF25,$AL$5) | AM25: =COUNTIF($B25:$AF25,$AM$5) | AN25: =COUNTIF($B25:$AF25,$AN$5)
A26: =Jan!A26 | AG26: =COUNTIF($B26:$AF26,$AG$5) | AH26: =COUNTIF($B26:$AF26,$AH$5) | AI26: =COUNTIF($B26:$AF26,$AI$5) | AJ26: =COUNTIF($B26:$AF26,$AJ$5) | AK26: =COUNTIF($B26:$AF26,$AK$5) | AL26: =COUNTIF($B26:$AF26,$AL$5) | AM26: =COUNTIF($B26:$AF26,$AM$5) | AN26: =COUNTIF($B26:$AF26,$AN$5)
AG27: =COUNTIF($B27:$AF27,$AG$5) | AH27: =COUNTIF($B27:$AF27,$AH$5) | AI27: =COUNTIF($B27:$AF27,$AI$5) | AJ27: =COUNTIF($B27:$AF27,$AJ$5) | AK27: =COUNTIF($B27:$AF27,$AK$5) | AL27: =COUNTIF($B27:$AF27,$AL$5) | AM27: =COUNTIF($B27:$AF27,$AM$5) | AN27: =COUNTIF($B27:$AF27,$AN$5)
A28: =Jan!A28 | AG28: =COUNTIF($B28:$AF28,$AG$5) | AH28: =COUNTIF($B28:$AF28,$AH$5) | AI28: =COUNTIF($B28:$AF28,$AI$5) | AJ28: =COUNTIF($B28:$AF28,$AJ$5) | AK28: =COUNTIF($B28:$AF28,$AK$5) | AL28: =COUNTIF($B28:$AF28,$AL$5) | AM28: =COUNTIF($B28:$AF28,$AM$5) | AN28: =COUNTIF($B28:$AF28,$AN$5)
AG29: =COUNTIF($B29:$AF29,$AG$5) | AH29: =COUNTIF($B29:$AF29,$AH$5) | AI29: =COUNTIF($B29:$AF29,$AI$5) | AJ29: =COUNTIF($B29:$AF29,$AJ$5) | AK29: =COUNTIF($B29:$AF29,$AK$5) | AL29: =COUNTIF($B29:$AF29,$AL$5) | AM29: =COUNTIF($B29:$AF29,$AM$5) | AN29: =COUNTIF($B29:$AF29,$AN$5)
A30: =Jan!A30 | AG30: =COUNTIF($B30:$AF30,$AG$5) | AH30: =COUNTIF($B30:$AF30,$AH$5) | AI30: =COUNTIF($B30:$AF30,$AI$5) | AJ30: =COUNTIF($B30:$AF30,$AJ$5) | AK30: =COUNTIF($B30:$AF30,$AK$5) | AL30: =COUNTIF($B30:$AF30,$AL$5) | AM30: =COUNTIF($B30:$AF30,$AM$5) | AN30: =COUNTIF($B30:$AF30,$AN$5)
AG31: =COUNTIF($B31:$AF31,$AG$5) | AH31: =COUNTIF($B31:$AF31,$AH$5) | AI31: =COUNTIF($B31:$AF31,$AI$5) | AJ31: =COUNTIF($B31:$AF31,$AJ$5) | AK31: =COUNTIF($B31:$AF31,$AK$5) | AL31: =COUNTIF($B31:$AF31,$AL$5) | AM31: =COUNTIF($B31:$AF31,$AM$5) | AN31: =COUNTIF($B31:$AF31,$AN$5)
A32: =Jan!A32 | AG32: =COUNTIF($B32:$AF32,$AG$5) | AH32: =COUNTIF($B32:$AF32,$AH$5) | AI32: =COUNTIF($B32:$AF32,$AI$5) | AJ32: =COUNTIF($B32:$AF32,$AJ$5) | AK32: =COUNTIF($B32:$AF32,$AK$5) | AL32: =COUNTIF($B32:$AF32,$AL$5) | AM32: =COUNTIF($B32:$AF32,$AM$5) | AN32: =COUNTIF($B32:$AF32,$AN$5)
AG33: =COUNTIF($B33:$AF33,$AG$5) | AH33: =COUNTIF($B33:$AF33,$AH$5) | AI33: =COUNTIF($B33:$AF33,$AI$5) | AJ33: =COUNTIF($B33:$AF33,$AJ$5) | AK33: =COUNTIF($B33:$AF33,$AK$5) | AL33: =COUNTIF($B33:$AF33,$AL$5) | AM33: =COUNTIF($B33:$AF33,$AM$5) | AN33: =COUNTIF($B33:$AF33,$AN$5)
A34: =Jan!A34 | AG34: =COUNTIF($B34:$AF34,$AG$5) | AH34: =COUNTIF($B34:$AF34,$AH$5) | AI34: =COUNTIF($B34:$AF34,$AI$5) | AJ34: =COUNTIF($B34:$AF34,$AJ$5) | AK34: =COUNTIF($B34:$AF34,$AK$5) | AL34: =COUNTIF($B34:$AF34,$AL$5) | AM34: =COUNTIF($B34:$AF34,$AM$5) | AN34: =COUNTIF($B34:$AF34,$AN$5)
AG35: =COUNTIF($B35:$AF35,$AG$5) | AH35: =COUNTIF($B35:$AF35,$AH$5) | AI35: =COUNTIF($B35:$AF35,$AI$5) | AJ35: =COUNTIF($B35:$AF35,$AJ$5) | AK35: =COUNTIF($B35:$AF35,$AK$5) | AL35: =COUNTIF($B35:$AF35,$AL$5) | AM35: =COUNTIF($B35:$AF35,$AM$5) | AN35: =COUNTIF($B35:$AF35,$AN$5)
A36: =Jan!A36 | AG36: =COUNTIF($B36:$AF36,$AG$5) | AH36: =COUNTIF($B36:$AF36,$AH$5) | AI36: =COUNTIF($B36:$AF36,$AI$5) | AJ36: =COUNTIF($B36:$AF36,$AJ$5) | AK36: =COUNTIF($B36:$AF36,$AK$5) | AL36: =COUNTIF($B36:$AF36,$AL$5) | AM36: =COUNTIF($B36:$AF36,$AM$5) | AN36: =COUNTIF($B36:$AF36,$AN$5)
AG37: =COUNTIF($B37:$AF37,$AG$5) | AH37: =COUNTIF($B37:$AF37,$AH$5) | AI37: =COUNTIF($B37:$AF37,$AI$5) | AJ37: =COUNTIF($B37:$AF37,$AJ$5) | AK37: =COUNTIF($B37:$AF37,$AK$5) | AL37: =COUNTIF($B37:$AF37,$AL$5) | AM37: =COUNTIF($B37:$AF37,$AM$5) | AN37: =COUNTIF($B37:$AF37,$AN$5)
A38: =Jan!A38 | AG38: =COUNTIF($B38:$AF38,$AG$5) | AH38: =COUNTIF($B38:$AF38,$AH$5) | AI38: =COUNTIF($B38:$AF38,$AI$5) | AJ38: =COUNTIF($B38:$AF38,$AJ$5) | AK38: =COUNTIF($B38:$AF38,$AK$5) | AL38: =COUNTIF($B38:$AF38,$AL$5) | AM38: =COUNTIF($B38:$AF38,$AM$5) | AN38: =COUNTIF($B38:$AF38,$AN$5)
AG39: =COUNTIF($B39:$AF39,$AG$5) | AH39: =COUNTIF($B39:$AF39,$AH$5) | AI39: =COUNTIF($B39:$AF39,$AI$5) | AJ39: =COUNTIF($B39:$AF39,$AJ$5) | AK39: =COUNTIF($B39:$AF39,$AK$5) | AL39: =COUNTIF($B39:$AF39,$AL$5) | AM39: =COUNTIF($B39:$AF39,$AM$5) | AN39: =COUNTIF($B39:$AF39,$AN$5)
A40: =Jan!A40 | AG40: =COUNTIF($B40:$AF40,$AG$5) | AH40: =COUNTIF($B40:$AF40,$AH$5) | AI40: =COUNTIF($B40:$AF40,$AI$5) | AJ40: =COUNTIF($B40:$AF40,$AJ$5) | AK40: =COUNTIF($B40:$AF40,$AK$5) | AL40: =COUNTIF($B40:$AF40,$AL$5) | AM40: =COUNTIF($B40:$AF40,$AM$5) | AN40: =COUNTIF($B40:$AF40,$AN$5)
AG41: =COUNTIF($B41:$AF41,$AG$5) | AH41: =COUNTIF($B41:$AF41,$AH$5) | AI41: =COUNTIF($B41:$AF41,$AI$5) | AJ41: =COUNTIF($B41:$AF41,$AJ$5) | AK41: =COUNTIF($B41:$AF41,$AK$5) | AL41: =COUNTIF($B41:$AF41,$AL$5) | AM41: =COUNTIF($B41:$AF41,$AM$5) | AN41: =COUNTIF($B41:$AF41,$AN$5)
...

Sheet Jun
A1: PREASONT REPORT IN THE MONTH OF JUN 2015
A3: A - ABSENT | B3: L - LEAVE | F3: WO - WEEKLY OFF | K3: PH - PUBLIC HOLIDAY | P3: CO - COMP. OFF | U3: ML - MEDICAL. LEAVE | AA3: ODK - WORK AT KARAI
B4: CALENDER DATES
A5: NAME | B5: 1 | C5: 2 | D5: 3 | E5: 4 | F5: 5 | G5: 6 | H5: 7 | I5: 8 | J5: 9 | K5: 10 | L5: 11 | M5: 12 | N5: 13 | O5: 14 | P5: 15 | Q5: 16 | R5: 17 | S5: 18 | T5: 19 | U5: 20 | V5: 21 | W5: 22 | X5: 23 | Y5: 24 | Z5: 25 | AA5: 26 | AB5: 27 | AC5: 28 | AD5: 29 | AE5: 30 | AF5: 31 | AG5: P | AH5: ODK | AI5: A | AJ5: L | AK5: WO | AL5: PH | AM5: CO | AN5: ML | AO5: REMARKS
A6: =Jan!A6 | AG6: =COUNTIF($B6:$AF6,$AG$5) | AH6: =COUNTIF($B6:$AF6,$AH$5) | AI6: =COUNTIF($B6:$AF6,$AI$5) | AJ6: =COUNTIF($B6:$AF6,$AJ$5) | AK6: =COUNTIF($B6:$AF6,$AK$5) | AL6: =COUNTIF($B6:$AF6,$AL$5) | AM6: =COUNTIF($B6:$AF6,$AM$5) | AN6: =COUNTIF($B6:$AF6,$AN$5) | AO6: 1 COM-OFF
AG7: =COUNTIF($B7:$AF7,$AG$5) | AH7: =COUNTIF($B7:$AF7,$AH$5) | AI7: =COUNTIF($B7:$AF7,$AI$5) | AJ7: =COUNTIF($B7:$AF7,$AJ$5) | AK7: =COUNTIF($B7:$AF7,$AK$5) | AL7: =COUNTIF($B7:$AF7,$AL$5) | AM7: =COUNTIF($B7:$AF7,$AM$5) | AN7: =COUNTIF($B7:$AF7,$AN$5)
A8: =Jan!A8 | AG8: =COUNTIF($B8:$AF8,$AG$5) | AH8: =COUNTIF($B8:$AF8,$AH$5) | AI8: =COUNTIF($B8:$AF8,$AI$5) | AJ8: =COUNTIF($B8:$AF8,$AJ$5) | AK8: =COUNTIF($B8:$AF8,$AK$5) | AL8: =COUNTIF($B8:$AF8,$AL$5) | AM8: =COUNTIF($B8:$AF8,$AM$5) | AN8: =COUNTIF($B8:$AF8,$AN$5)
AG9: =COUNTIF($B9:$AF9,$AG$5) | AH9: =COUNTIF($B9:$AF9,$AH$5) | AI9: =COUNTIF($B9:$AF9,$AI$5) | AJ9: =COUNTIF($B9:$AF9,$AJ$5) | AK9: =COUNTIF($B9:$AF9,$AK$5) | AL9: =COUNTIF($B9:$AF9,$AL$5) | AM9: =COUNTIF($B9:$AF9,$AM$5) | AN9: =COUNTIF($B9:$AF9,$AN$5)
A10: =Jan!A10 | AG10: =COUNTIF($B10:$AF10,$AG$5) | AH10: =COUNTIF($B10:$AF10,$AH$5) | AI10: =COUNTIF($B10:$AF10,$AI$5) | AJ10: =COUNTIF($B10:$AF10,$AJ$5) | AK10: =COUNTIF($B10:$AF10,$AK$5) | AL10: =COUNTIF($B10:$AF10,$AL$5) | AM10: =COUNTIF($B10:$AF10,$AM$5) | AN10: =COUNTIF($B10:$AF10,$AN$5)
AG11: =COUNTIF($B11:$AF11,$AG$5) | AH11: =COUNTIF($B11:$AF11,$AH$5) | AI11: =COUNTIF($B11:$AF11,$AI$5) | AJ11: =COUNTIF($B11:$AF11,$AJ$5) | AK11: =COUNTIF($B11:$AF11,$AK$5) | AL11: =COUNTIF($B11:$AF11,$AL$5) | AM11: =COUNTIF($B11:$AF11,$AM$5) | AN11: =COUNTIF($B11:$AF11,$AN$5)
A12: =Jan!A12 | AG12: =COUNTIF($B12:$AF12,$AG$5) | AH12: =COUNTIF($B12:$AF12,$AH$5) | AI12: =COUNTIF($B12:$AF12,$AI$5) | AJ12: =COUNTIF($B12:$AF12,$AJ$5) | AK12: =COUNTIF($B12:$AF12,$AK$5) | AL12: =COUNTIF($B12:$AF12,$AL$5) | AM12: =COUNTIF($B12:$AF12,$AM$5) | AN12: =COUNTIF($B12:$AF12,$AN$5)
AG13: =COUNTIF($B13:$AF13,$AG$5) | AH13: =COUNTIF($B13:$AF13,$AH$5) | AI13: =COUNTIF($B13:$AF13,$AI$5) | AJ13: =COUNTIF($B13:$AF13,$AJ$5) | AK13: =COUNTIF($B13:$AF13,$AK$5) | AL13: =COUNTIF($B13:$AF13,$AL$5) | AM13: =COUNTIF($B13:$AF13,$AM$5) | AN13: =COUNTIF($B13:$AF13,$AN$5)
A14: =Jan!A14 | AG14: =COUNTIF($B14:$AF14,$AG$5) | AH14: =COUNTIF($B14:$AF14,$AH$5) | AI14: =COUNTIF($B14:$AF14,$AI$5) | AJ14: =COUNTIF($B14:$AF14,$AJ$5) | AK14: =COUNTIF($B14:$AF14,$AK$5) | AL14: =COUNTIF($B14:$AF14,$AL$5) | AM14: =COUNTIF($B14:$AF14,$AM$5) | AN14: =COUNTIF($B14:$AF14,$AN$5)
AG15: =COUNTIF($B15:$AF15,$AG$5) | AH15: =COUNTIF($B15:$AF15,$AH$5) | AI15: =COUNTIF($B15:$AF15,$AI$5) | AJ15: =COUNTIF($B15:$AF15,$AJ$5) | AK15: =COUNTIF($B15:$AF15,$AK$5) | AL15: =COUNTIF($B15:$AF15,$AL$5) | AM15: =COUNTIF($B15:$AF15,$AM$5) | AN15: =COUNTIF($B15:$AF15,$AN$5)
A16: =Jan!A16 | AG16: =COUNTIF($B16:$AF16,$AG$5) | AH16: =COUNTIF($B16:$AF16,$AH$5) | AI16: =COUNTIF($B16:$AF16,$AI$5) | AJ16: =COUNTIF($B16:$AF16,$AJ$5) | AK16: =COUNTIF($B16:$AF16,$AK$5) | AL16: =COUNTIF($B16:$AF16,$AL$5) | AM16: =COUNTIF($B16:$AF16,$AM$5) | AN16: =COUNTIF($B16:$AF16,$AN$5)
AG17: =COUNTIF($B17:$AF17,$AG$5) | AH17: =COUNTIF($B17:$AF17,$AH$5) | AI17: =COUNTIF($B17:$AF17,$AI$5) | AJ17: =COUNTIF($B17:$AF17,$AJ$5) | AK17: =COUNTIF($B17:$AF17,$AK$5) | AL17: =COUNTIF($B17:$AF17,$AL$5) | AM17: =COUNTIF($B17:$AF17,$AM$5) | AN17: =COUNTIF($B17:$AF17,$AN$5)
A18: =Jan!A18 | AG18: =COUNTIF($B18:$AF18,$AG$5) | AH18: =COUNTIF($B18:$AF18,$AH$5) | AI18: =COUNTIF($B18:$AF18,$AI$5) | AJ18: =COUNTIF($B18:$AF18,$AJ$5) | AK18: =COUNTIF($B18:$AF18,$AK$5) | AL18: =COUNTIF($B18:$AF18,$AL$5) | AM18: =COUNTIF($B18:$AF18,$AM$5) | AN18: =COUNTIF($B18:$AF18,$AN$5)
AG19: =COUNTIF($B19:$AF19,$AG$5) | AH19: =COUNTIF($B19:$AF19,$AH$5) | AI19: =COUNTIF($B19:$AF19,$AI$5) | AJ19: =COUNTIF($B19:$AF19,$AJ$5) | AK19: =COUNTIF($B19:$AF19,$AK$5) | AL19: =COUNTIF($B19:$AF19,$AL$5) | AM19: =COUNTIF($B19:$AF19,$AM$5) | AN19: =COUNTIF($B19:$AF19,$AN$5)
A20: =Jan!A20 | AG20: =COUNTIF($B20:$AF20,$AG$5) | AH20: =COUNTIF($B20:$AF20,$AH$5) | AI20: =COUNTIF($B20:$AF20,$AI$5) | AJ20: =COUNTIF($B20:$AF20,$AJ$5) | AK20: =COUNTIF($B20:$AF20,$AK$5) | AL20: =COUNTIF($B20:$AF20,$AL$5) | AM20: =COUNTIF($B20:$AF20,$AM$5) | AN20: =COUNTIF($B20:$AF20,$AN$5)
AG21: =COUNTIF($B21:$AF21,$AG$5) | AH21: =COUNTIF($B21:$AF21,$AH$5) | AI21: =COUNTIF($B21:$AF21,$AI$5) | AJ21: =COUNTIF($B21:$AF21,$AJ$5) | AK21: =COUNTIF($B21:$AF21,$AK$5) | AL21: =COUNTIF($B21:$AF21,$AL$5) | AM21: =COUNTIF($B21:$AF21,$AM$5) | AN21: =COUNTIF($B21:$AF21,$AN$5)
A22: =Jan!A22 | AG22: =COUNTIF($B22:$AF22,$AG$5) | AH22: =COUNTIF($B22:$AF22,$AH$5) | AI22: =COUNTIF($B22:$AF22,$AI$5) | AJ22: =COUNTIF($B22:$AF22,$AJ$5) | AK22: =COUNTIF($B22:$AF22,$AK$5) | AL22: =COUNTIF($B22:$AF22,$AL$5) | AM22: =COUNTIF($B22:$AF22,$AM$5) | AN22: =COUNTIF($B22:$AF22,$AN$5)
AG23: =COUNTIF($B23:$AF23,$AG$5) | AH23: =COUNTIF($B23:$AF23,$AH$5) | AI23: =COUNTIF($B23:$AF23,$AI$5) | AJ23: =COUNTIF($B23:$AF23,$AJ$5) | AK23: =COUNTIF($B23:$AF23,$AK$5) | AL23: =COUNTIF($B23:$AF23,$AL$5) | AM23: =COUNTIF($B23:$AF23,$AM$5) | AN23: =COUNTIF($B23:$AF23,$AN$5)
A24: =Jan!A24 | AG24: =COUNTIF($B24:$AF24,$AG$5) | AH24: =COUNTIF($B24:$AF24,$AH$5) | AI24: =COUNTIF($B24:$AF24,$AI$5) | AJ24: =COUNTIF($B24:$AF24,$AJ$5) | AK24: =COUNTIF($B24:$AF24,$AK$5) | AL24: =COUNTIF($B24:$AF24,$AL$5) | AM24: =COUNTIF($B24:$AF24,$AM$5) | AN24: =COUNTIF($B24:$AF24,$AN$5)
AG25: =COUNTIF($B25:$AF25,$AG$5) | AH25: =COUNTIF($B25:$AF25,$AH$5) | AI25: =COUNTIF($B25:$AF25,$AI$5) | AJ25: =COUNTIF($B25:$AF25,$AJ$5) | AK25: =COUNTIF($B25:$AF25,$AK$5) | AL25: =COUNTIF($B25:$AF25,$AL$5) | AM25: =COUNTIF($B25:$AF25,$AM$5) | AN25: =COUNTIF($B25:$AF25,$AN$5)
A26: =Jan!A26 | AG26: =COUNTIF($B26:$AF26,$AG$5) | AH26: =COUNTIF($B26:$AF26,$AH$5) | AI26: =COUNTIF($B26:$AF26,$AI$5) | AJ26: =COUNTIF($B26:$AF26,$AJ$5) | AK26: =COUNTIF($B26:$AF26,$AK$5) | AL26: =COUNTIF($B26:$AF26,$AL$5) | AM26: =COUNTIF($B26:$AF26,$AM$5) | AN26: =COUNTIF($B26:$AF26,$AN$5)
